Workbook
Name Division: '[1]Not Available'!$B$2:$B$7
Name Division: 'Not Available'!$B$2:$B$7
Name Status: '[1]Not Available'!$B$10:$B$13
Name Status: 'Not Available'!$B$10:$B$13
Name Status: 'Not Available'!$B$10:$B$13

Sheet 説明
A2: ① | B2: 案件．要員情報シートについて
B3: ▲今月のため対応された各案件、プロジェクト管理と他のテストの計画と実績人間を報告することです。 | K3: ※ | L3: メモ
B4: 列名の説明 | C4: 列名 | D4: 内容 | L4: 今週⇒ | M4: 「先週の定例会の日から今週の水曜日までのカウント」
C5: No.列 | D5: 連番 | L5: 来週⇒ | M5: 「今週の定例会の日から来週の水曜日までのカウント」
C6: ステータス | D6: 案件のステータス「未着手、進行中、レビュー待ち、完了」
C7: 区分 | D7: 案件のカテゴリー | L7: ・11月の計画工数の作成方法の説明
C8: DIR 担当 | D8: 案件依頼しているDIR担当者名 | L8: ・11月の計画工数と実績工数の差異の理由
C9: 案件管理コード（DAT) | D9: DAT側でのWBS管理コード | L9: ・12月の計画工数（案件毎の内訳情報も）および過不足工数の説明
C10: 案件管理コード（DIR) | D10: DIR側からの管理コード
C11: 案件 | D11: 今週中対応された案件名
C12: 備考 | D12: リマーク
J14: http://w3ttsvn10/svn/webbroker3_pr/ミャンマーDAT/30_見積り依頼/オンライン開発(2022年9月~2023年2月)についての見積書.xlsx
B15: 案件の計画工数作成方法の説明 | C15: 案件名 | D15: 計画工数作成方法
C16: 定型案件 | D16: WBSを参考し、案件の範囲とメンバーのスキルに依存して作成しています。
C17: (全社)脆弱性対応（2022年）_パス・トラバーサル対応 | D17: ◆他のプロジェクトにはFASE Formを提出して対応するプロジェクトがあります。しかし、WB4にはありません。プロジェクトの計画をPMが上記のことなどを向けて作成しています。
D18: ◆「(全社)脆弱性対応（2022年）_パス・トラバーサル対応」は徳田様が9月から12月まで各月に４人間として企画しました。
D19: ◆DIRと月次会議後には、サービス機能テストもする可能性がありますので、イェさんが２月まで各月に４人間として企画しました。 (9月~2月)の計画人間⇒25.18 各月の計画人間 ⇒ 4.19 (25.18/6)
B21: 計画工数と実績工数の差異の理由 | C21: 案件名 | D21: 理由
C22: 定型案件と (全社)脆弱性対応（2022年）_パス・トラバーサル対応 | D22: ◆DIRから計画を立っていないし、PMが自分で計画したので異なりました。
D23: ◆仕事がありますが、様々な理由で (エラーが発生など)停止しているので異なりました。 ◆仕事が止まる時、メンバーのスキルアップのため研修しています。
B25: ▲DATメンバーが対応しているプロジェクト管理タスクは６つあります。
B27: プロジェクト管理の計画工数作成方法の説明 | C27: タスク名 | D27: 計画工数作成方法
C28: DATチーム会議 | D28: ◆毎日30分(0.5 hr)かかります。 ◆全メンバーが出席しています。 ◆一人⇒(0.5 x Working Day)
C29: DIRとの定例会 | D29: ◆毎週1時間かかります。 ◆全メンバーが出席しています。 ◆一人⇒(１ x week count of a month)
C30: 日次報告書 | D30: ◆DATの社内システム(WHM)とThincの日次報告書に報告記入する時間です。 ◆毎日30分(0.5 hr)かかります。 ◆全メンバーがやっています。 ◆一人⇒(0.5 x Working Day)
C31: 週次報告 | D31: ◆毎週の水曜日DIRへ送信する週次報告作成時間と毎週の金曜日DAT管理人送信する週次報告作成時間 ◆毎週３時間かかります。 ◆PMだけやっています。 ◆一人⇒(0.5 x Working Day)
C32: プロジェクト管理、メール送受信、WBS管理、Redmine管理 | D32: ◆メール送受信時間、WBS作成時間、Redmine管理時間と他の報告作成時間です。 ◆毎日PMは３時間、二人のリーダーは30分かかる。 ◆(3 x Working Day)+(0.5 x Working Day)+(0.5 x Working Day)
C33: メンバーサポート | D33: ◆PMとリーダーが他のメンバーにサポートする時間です。 ◆毎日PMと二人のリーダーは1時間かかる。 ◆(1 x Working Day)+(1 x Working Day)+(1 x Working Day)
B35: 計画工数と実績工数の差異の理由 | C35: 案件名 | D35: 理由
C36: DATチーム会議 | D36: いつものは計画と実績が合っています。
C37: DIRとの定例会 | D37: 計画は1時間ですが、実際は30分以下かかるので 異なりました。
C38: 日次報告書 | D38: いつものは計画と実績が合っています。
C39: 週次報告 | D39: 計画を記入していますが、実績は計算する時には下記のプロジェクト管理テクストに追加して計算しています。 そして、週次報告の実績は'0'になっています。
C40: プロジェクト管理、メール送受信、WBS管理、Redmine管理 | D40: ◆毎日PMのため３時間として予定されていますが、週次報告作成時間を追加し、他の管理タスクがあるため計画と実績が異なります。 ◆毎日二人のリーダーのため30分として予定されていますが、管理タクスがない日もあるので計画と実績が異なります。
C41: メンバーサポート | D41: メンバーはサポートが不要な日もあるので計画と実績が異なります。
B43: ▲その他のタクスには案件と管理以外のタクス例えばJinwa研修やDAT社内作業などのタクスです。
B45: プロジェクト管理の計画工数作成方法の説明 | C45: タスク名 | D45: 計画工数作成方法
C46: WB4 Internal Training | D46: 新入社員がいる月には計画を作成しています。 今は新入社員がいないので計画は０になりました。
C47: JINWA Training(Class Hours) | D47: DATの社内報告書の計画時間と合わせるため、計画が０になりました。
C48: JINWA Training(Practicals) | D48: ◆メンバー４人が毎日3時間対応しています。 ◆一人⇒(３x Working Day)
...

Sheet 案件．要員情報まとめ
A1: 案件．要員情報 | S1: Total Member - 7 | W1: Contract Member - 5
S2: FOC Member - 2
A3: ■案件
A4: No. | B4: ステータス | C4: 区分 | D4: DIR 担当 | E4: 案件管理コード（DAT) | F4: 案件管理コード（DIR) | G4: 案件 | H4: 計画 (DIR) | I4: 計画 (DAT) | J4: 実績 | K4: 着手日 | L4: 完了日 | M4: 備考/理由 | N4: 工数（人月）
O5: 4月 | P5: 5月 | Q5: 6月 | R5: 7月 | S5: 8月 | T5: 9月 | U5: 10月 | V5: 11月 | W5: 12月 | X5: 1月 | Y5: 2月 | Z5: 3月
A6: 1 | B6: 着手中 | C6: その他 | D6: 飯田 | E6: BW1 | F6: A5207110 | G6: 【案件依頼】ビルド作業を対応 | N6: 計画 | O6: =SUM('案件．要員情報'!O7:U7) -> 0.45833333 | P6: =SUM('案件．要員情報'!V7:AA7) -> 0.21052632 | Q6: =SUM('案件．要員情報'!AB7:AG7) -> 0.27272727 | R6: =SUM('案件．要員情報'!AH7:AM7) -> 0.12121212 | S6: =SUM('案件．要員情報'!AN7:AS7) -> 0.20952381 | T6: =SUM('案件．要員情報'!AT7:AY7) -> 0.32121212 | U6: =SUM('案件．要員情報'!AZ7:BF7) -> 0.33333333 | V6: =SUM('案件．要員情報'!BG7:BN7) -> 0 | W6: =SUM('案件．要員情報'!BO7:BV7) -> 0 | X6: =SUM('案件．要員情報'!BW7:CD7) -> 0 | Y6: =SUM('案件．要員情報'!CE7:CL7) -> 0 | Z6: =SUM('案件．要員情報'!CM7:CT7) -> 0 | AA6: =SUM(O6:Z6) -> 1.9268683
N7: 実績 | O7: =SUM('案件．要員情報'!O8:U8) -> 0.40833333 | P7: =SUM('案件．要員情報'!V8:AA8) -> 0.19649123 | Q7: =SUM('案件．要員情報'!AB8:AG8) -> 0.26363636 | R7: =SUM('案件．要員情報'!AH8:AM8) -> 0.11818182 | S7: =SUM('案件．要員情報'!AN8:AS8) -> 0.20952381 | T7: =SUM('案件．要員情報'!AT8:AY8) -> 0.2969697 | U7: =SUM('案件．要員情報'!AZ8:BF8) -> 0.06 | V7: =SUM('案件．要員情報'!BG8:BN8) -> 0 | W7: =SUM('案件．要員情報'!BO8:BV8) -> 0 | X7: =SUM('案件．要員情報'!BW8:CD8) -> 0 | Y7: =SUM('案件．要員情報'!CE8:CL8) -> 0 | Z7: =SUM('案件．要員情報'!CM8:CT8) -> 0 | AA7: =SUM(O7:Z7) -> 1.5531362
A8: 2 | B8: 完了 | C8: その他 | D8: 山本 | E8: WA2 | G8: 【開発依頼】作業の自動化_UATヘルスチェック | N8: 計画 | O8: =SUM('案件．要員情報'!O9:U9) -> 0.041666667 | P8: =SUM('案件．要員情報'!V9:AA9) -> 0 | Q8: =SUM('案件．要員情報'!AB9:AG9) -> 0 | R8: =SUM('案件．要員情報'!AH9:AM9) -> 0 | S8: =SUM('案件．要員情報'!AN9:AS9) -> 0 | T8: =SUM('案件．要員情報'!AT9:AY9) -> 0 | U8: =SUM('案件．要員情報'!AZ9:BF9) -> 0 | V8: =SUM('案件．要員情報'!BG9:BN9) -> 0 | W8: =SUM('案件．要員情報'!BO9:BV9) -> 0 | X8: =SUM('案件．要員情報'!BW9:CD9) -> 0 | Y8: =SUM('案件．要員情報'!CE9:CL9) -> 0 | Z8: =SUM('案件．要員情報'!CM9:CT9) -> 0 | AA8: =SUM(O8:Z8) -> 0.041666667
N9: 実績 | O9: =SUM('案件．要員情報'!O10:U10) -> 0.029166667 | P9: =SUM('案件．要員情報'!V10:AA10) -> 0 | Q9: =SUM('案件．要員情報'!AB10:AG10) -> 0 | R9: =SUM('案件．要員情報'!AH10:AM10) -> 0 | S9: =SUM('案件．要員情報'!AN10:AS10) -> 0 | T9: =SUM('案件．要員情報'!AT10:AY10) -> 0 | U9: =SUM('案件．要員情報'!AZ10:BF10) -> 0 | V9: =SUM('案件．要員情報'!BG10:BN10) -> 0 | W9: =SUM('案件．要員情報'!BO10:BV10) -> 0 | X9: =SUM('案件．要員情報'!BW10:CD10) -> 0 | Y9: =SUM('案件．要員情報'!CE10:CL10) -> 0 | Z9: =SUM('案件．要員情報'!CM10:CT10) -> 0 | AA9: =SUM(O9:Z9) -> 0.029166667
A10: 3 | B10: 完了 | C10: その他 | D10: 仲井 | E10: WA6 | F10: PBxxxxxxxx | G10: 【開発依頼】作業の自動化・効率化_エラーメッセージ一覧作成 | N10: 計画 | O10: =SUM('案件．要員情報'!O11:U11) -> 0.66666667 | P10: =SUM('案件．要員情報'!V11:AA11) -> 0 | Q10: =SUM('案件．要員情報'!AB11:AG11) -> 0 | R10: =SUM('案件．要員情報'!AH11:AM11) -> 0 | S10: =SUM('案件．要員情報'!AN11:AS11) -> 0 | T10: =SUM('案件．要員情報'!AT11:AY11) -> 0 | U10: =SUM('案件．要員情報'!AZ11:BF11) -> 0 | V10: =SUM('案件．要員情報'!BG11:BN11) -> 0 | W10: =SUM('案件．要員情報'!BO11:BV11) -> 0 | X10: =SUM('案件．要員情報'!BW11:CD11) -> 0 | Y10: =SUM('案件．要員情報'!CE11:CL11) -> 0 | Z10: =SUM('案件．要員情報'!CM11:CT11) -> 0 | AA10: =SUM(O10:Z10) -> 0.66666667
N11: 実績 | O11: =SUM('案件．要員情報'!O12:U12) -> 0.61666667 | P11: =SUM('案件．要員情報'!V12:AA12) -> 0 | Q11: =SUM('案件．要員情報'!AB12:AG12) -> 0 | R11: =SUM('案件．要員情報'!AH12:AM12) -> 0 | S11: =SUM('案件．要員情報'!AN12:AS12) -> 0 | T11: =SUM('案件．要員情報'!AT12:AY12) -> 0 | U11: =SUM('案件．要員情報'!AZ12:BF12) -> 0 | V11: =SUM('案件．要員情報'!BG12:BN12) -> 0 | W11: =SUM('案件．要員情報'!BO12:BV12) -> 0 | X11: =SUM('案件．要員情報'!BW12:CD12) -> 0 | Y11: =SUM('案件．要員情報'!CE12:CL12) -> 0 | Z11: =SUM('案件．要員情報'!CM12:CT12) -> 0 | AA11: =SUM(O11:Z11) -> 0.61666667
A12: 4 | B12: 完了 | C12: その他 | D12: 安藤 | E12: BT7 | F12: PBxxxxxxxx | G12: 【開発依頼】4631_PBxxxxxxxx_(90)バッチ機DISC使用率軽減対応 | N12: 計画 | O12: =SUM('案件．要員情報'!O13:U13) -> 0.58333333 | P12: =SUM('案件．要員情報'!V13:AA13) -> 0 | Q12: =SUM('案件．要員情報'!AB13:AG13) -> 0.3030303 | R12: =SUM('案件．要員情報'!AH13:AM13) -> 0 | S12: =SUM('案件．要員情報'!AN13:AS13) -> 0 | T12: =SUM('案件．要員情報'!AT13:AY13) -> 0.13333333 | U12: =SUM('案件．要員情報'!AZ13:BF13) -> 0 | V12: =SUM('案件．要員情報'!BG13:BN13) -> 0 | W12: =SUM('案件．要員情報'!BO13:BV13) -> 0 | X12: =SUM('案件．要員情報'!BW13:CD13) -> 0 | Y12: =SUM('案件．要員情報'!CE13:CL13) -> 0 | Z12: =SUM('案件．要員情報'!CM13:CT13) -> 0 | AA12: =SUM(O12:Z12) -> 1.019697
N13: 実績 | O13: =SUM('案件．要員情報'!O14:U14) -> 0.54791667 | P13: =SUM('案件．要員情報'!V14:AA14) -> 0 | Q13: =SUM('案件．要員情報'!AB14:AG14) -> 0.26363636 | R13: =SUM('案件．要員情報'!AH14:AM14) -> 0 | S13: =SUM('案件．要員情報'!AN14:AS14) -> 0 | T13: =SUM('案件．要員情報'!AT14:AY14) -> 0.12424242 | U13: =SUM('案件．要員情報'!AZ14:BF14) -> 0 | V13: =SUM('案件．要員情報'!BG14:BN14) -> 0 | W13: =SUM('案件．要員情報'!BO14:BV14) -> 0 | X13: =SUM('案件．要員情報'!BW14:CD14) -> 0 | Y13: =SUM('案件．要員情報'!CE14:CL14) -> 0 | Z13: =SUM('案件．要員情報'!CM14:CT14) -> 0 | AA13: =SUM(O13:Z13) -> 0.93579545
A14: 5 | B14: 完了 | C14: 定型 | D14: 山田 | E14: F201 | F14: PB00202063 | G14: 【定型】信用取引金利優遇条件設定依頼 | N14: 計画 | O14: =SUM('案件．要員情報'!O15:U15) -> 0.375 | P14: =SUM('案件．要員情報'!V15:AA15) -> 0 | Q14: =SUM('案件．要員情報'!AB15:AG15) -> 0 | R14: =SUM('案件．要員情報'!AH15:AM15) -> 0 | S14: =SUM('案件．要員情報'!AN15:AS15) -> 0 | T14: =SUM('案件．要員情報'!AT15:AY15) -> 0 | U14: =SUM('案件．要員情報'!AZ15:BF15) -> 0 | V14: =SUM('案件．要員情報'!BG15:BN15) -> 0 | W14: =SUM('案件．要員情報'!BO15:BV15) -> 0 | X14: =SUM('案件．要員情報'!BW15:CD15) -> 0 | Y14: =SUM('案件．要員情報'!CE15:CL15) -> 0 | Z14: =SUM('案件．要員情報'!CM15:CT15) -> 0 | AA14: =SUM(O14:Z14) -> 0.375
N15: 実績 | O15: =SUM('案件．要員情報'!O16:U16) -> 0.32083333 | P15: =SUM('案件．要員情報'!V16:AA16) -> 0 | Q15: =SUM('案件．要員情報'!AB16:AG16) -> 0 | R15: =SUM('案件．要員情報'!AH16:AM16) -> 0 | S15: =SUM('案件．要員情報'!AN16:AS16) -> 0 | T15: =SUM('案件．要員情報'!AT16:AY16) -> 0 | U15: =SUM('案件．要員情報'!AZ16:BF16) -> 0 | V15: =SUM('案件．要員情報'!BG16:BN16) -> 0 | W15: =SUM('案件．要員情報'!BO16:BV16) -> 0 | X15: =SUM('案件．要員情報'!BW16:CD16) -> 0 | Y15: =SUM('案件．要員情報'!CE16:CL16) -> 0 | Z15: =SUM('案件．要員情報'!CM16:CT16) -> 0 | AA15: =SUM(O15:Z15) -> 0.32083333
A16: 6 | B16: 完了 | C16: その他 | D16: 永盛 | E16: PR15 | F16: PD00400226 | G16: 【LISA】【フィデア】(1E)(1Y)銀行合併対応 開発フェーズ（LISA） | N16: 計画 | O16: =SUM('案件．要員情報'!O17:U17) -> 0.041666667 | P16: =SUM('案件．要員情報'!V17:AA17) -> 0.056140351 | Q16: =SUM('案件．要員情報'!AB17:AG17) -> 0.060606061 | R16: =SUM('案件．要員情報'!AH17:AM17) -> 0 | S16: =SUM('案件．要員情報'!AN17:AS17) -> 0 | T16: =SUM('案件．要員情報'!AT17:AY17) -> 0 | U16: =SUM('案件．要員情報'!AZ17:BF17) -> 0 | V16: =SUM('案件．要員情報'!BG17:BN17) -> 0 | W16: =SUM('案件．要員情報'!BO17:BV17) -> 0 | X16: =SUM('案件．要員情報'!BW17:CD17) -> 0 | Y16: =SUM('案件．要員情報'!CE17:CL17) -> 0 | Z16: =SUM('案件．要員情報'!CM17:CT17) -> 0 | AA16: =SUM(O16:Z16) -> 0.15841308
N17: 実績 | O17: =SUM('案件．要員情報'!O18:U18) -> 0.025 | P17: =SUM('案件．要員情報'!V18:AA18) -> 0.031578947 | Q17: =SUM('案件．要員情報'!AB18:AG18) -> 0.036363636 | R17: =SUM('案件．要員情報'!AH18:AM18) -> 0 | S17: =SUM('案件．要員情報'!AN18:AS18) -> 0 | T17: =SUM('案件．要員情報'!AT18:AY18) -> 0 | U17: =SUM('案件．要員情報'!AZ18:BF18) -> 0 | V17: =SUM('案件．要員情報'!BG18:BN18) -> 0 | W17: =SUM('案件．要員情報'!BO18:BV18) -> 0 | X17: =SUM('案件．要員情報'!BW18:CD18) -> 0 | Y17: =SUM('案件．要員情報'!CE18:CL18) -> 0 | Z17: =SUM('案件．要員情報'!CM18:CT18) -> 0 | AA17: =SUM(O17:Z17) -> 0.092942584
A18: 7 | B18: 完了 | C18: 定型 | D18: 山田 | E18: F202 | F18: PB00202062 | G18: 【定型】投資家画面の文言変更 | N18: 計画 | O18: =SUM('案件．要員情報'!O19:U19) -> 0.43333333 | P18: =SUM('案件．要員情報'!V19:AA19) -> 0 | Q18: =SUM('案件．要員情報'!AB19:AG19) -> 0 | R18: =SUM('案件．要員情報'!AH19:AM19) -> 0 | S18: =SUM('案件．要員情報'!AN19:AS19) -> 0 | T18: =SUM('案件．要員情報'!AT19:AY19) -> 0 | U18: =SUM('案件．要員情報'!AZ19:BF19) -> 0 | V18: =SUM('案件．要員情報'!BG19:BN19) -> 0 | W18: =SUM('案件．要員情報'!BO19:BV19) -> 0 | X18: =SUM('案件．要員情報'!BW19:CD19) -> 0 | Y18: =SUM('案件．要員情報'!CE19:CL19) -> 0 | Z18: =SUM('案件．要員情報'!CM19:CT19) -> 0 | AA18: =SUM(O18:Z18) -> 0.43333333
N19: 実績 | O19: =SUM('案件．要員情報'!O20:U20) -> 0.40625 | P19: =SUM('案件．要員情報'!V20:AA20) -> 0 | Q19: =SUM('案件．要員情報'!AB20:AG20) -> 0 | R19: =SUM('案件．要員情報'!AH20:AM20) -> 0 | S19: =SUM('案件．要員情報'!AN20:AS20) -> 0 | T19: =SUM('案件．要員情報'!AT20:AY20) -> 0 | U19: =SUM('案件．要員情報'!AZ20:BF20) -> 0 | V19: =SUM('案件．要員情報'!BG20:BN20) -> 0 | W19: =SUM('案件．要員情報'!BO20:BV20) -> 0 | X19: =SUM('案件．要員情報'!BW20:CD20) -> 0 | Y19: =SUM('案件．要員情報'!CE20:CL20) -> 0 | Z19: =SUM('案件．要員情報'!CM20:CT20) -> 0 | AA19: =SUM(O19:Z19) -> 0.40625
A20: 8 | B20: 完了 | C20: 定型 | D20: 山田 | E20: F203 | F20: PB00202085 | G20: 【定型】株式委託手数料プランの名前変更 | N20: 計画 | O20: =SUM('案件．要員情報'!O21:U21) -> 0.29166667 | P20: =SUM('案件．要員情報'!V21:AA21) -> 0 | Q20: =SUM('案件．要員情報'!AB21:AG21) -> 0 | R20: =SUM('案件．要員情報'!AH21:AM21) -> 0 | S20: =SUM('案件．要員情報'!AN21:AS21) -> 0 | T20: =SUM('案件．要員情報'!AT21:AY21) -> 0 | U20: =SUM('案件．要員情報'!AZ21:BF21) -> 0 | V20: =SUM('案件．要員情報'!BG21:BN21) -> 0 | W20: =SUM('案件．要員情報'!BO21:BV21) -> 0 | X20: =SUM('案件．要員情報'!BW21:CD21) -> 0 | Y20: =SUM('案件．要員情報'!CE21:CL21) -> 0 | Z20: =SUM('案件．要員情報'!CM21:CT21) -> 0 | AA20: =SUM(O20:Z20) -> 0.29166667
N21: 実績 | O21: =SUM('案件．要員情報'!O22:U22) -> 0.25 | P21: =SUM('案件．要員情報'!V22:AA22) -> 0 | Q21: =SUM('案件．要員情報'!AB22:AG22) -> 0 | R21: =SUM('案件．要員情報'!AH22:AM22) -> 0 | S21: =SUM('案件．要員情報'!AN22:AS22) -> 0 | T21: =SUM('案件．要員情報'!AT22:AY22) -> 0 | U21: =SUM('案件．要員情報'!AZ22:BF22) -> 0 | V21: =SUM('案件．要員情報'!BG22:BN22) -> 0 | W21: =SUM('案件．要員情報'!BO22:BV22) -> 0 | X21: =SUM('案件．要員情報'!BW22:CD22) -> 0 | Y21: =SUM('案件．要員情報'!CE22:CL22) -> 0 | Z21: =SUM('案件．要員情報'!CM22:CT22) -> 0 | AA21: =SUM(O21:Z21) -> 0.25
A22: 9 | B22: 完了 | C22: 定型 | D22: 山田 | E22: F204 | G22: 【定型】クイック入金ページの注意文言修正依頼 | N22: 計画 | O22: =SUM('案件．要員情報'!O23:U23) -> 0.20833333 | P22: =SUM('案件．要員情報'!V23:AA23) -> 0 | Q22: =SUM('案件．要員情報'!AB23:AG23) -> 0 | R22: =SUM('案件．要員情報'!AH23:AM23) -> 0 | S22: =SUM('案件．要員情報'!AN23:AS23) -> 0 | T22: =SUM('案件．要員情報'!AT23:AY23) -> 0 | U22: =SUM('案件．要員情報'!AZ23:BF23) -> 0 | V22: =SUM('案件．要員情報'!BG23:BN23) -> 0 | W22: =SUM('案件．要員情報'!BO23:BV23) -> 0 | X22: =SUM('案件．要員情報'!BW23:CD23) -> 0 | Y22: =SUM('案件．要員情報'!CE23:CL23) -> 0 | Z22: =SUM('案件．要員情報'!CM23:CT23) -> 0 | AA22: =SUM(O22:Z22) -> 0.20833333
N23: 実績 | O23: =SUM('案件．要員情報'!O24:U24) -> 0.19791667 | P23: =SUM('案件．要員情報'!V24:AA24) -> 0 | Q23: =SUM('案件．要員情報'!AB24:AG24) -> 0 | R23: =SUM('案件．要員情報'!AH24:AM24) -> 0 | S23: =SUM('案件．要員情報'!AN24:AS24) -> 0 | T23: =SUM('案件．要員情報'!AT24:AY24) -> 0 | U23: =SUM('案件．要員情報'!AZ24:BF24) -> 0 | V23: =SUM('案件．要員情報'!BG24:BN24) -> 0 | W23: =SUM('案件．要員情報'!BO24:BV24) -> 0 | X23: =SUM('案件．要員情報'!BW24:CD24) -> 0 | Y23: =SUM('案件．要員情報'!CE24:CL24) -> 0 | Z23: =SUM('案件．要員情報'!CM24:CT24) -> 0 | AA23: =SUM(O23:Z23) -> 0.19791667
A24: 10 | B24: 完了 | C24: その他 | D24: 鈴木 | E24: EPM13 | F24: PC00115425 | G24: 4574_PC00115425_(全社)信用取引残高報告のフォーマット変更に係る対応 | N24: 計画 | O24: =SUM('案件．要員情報'!O25:U25) -> 0.80833333 | P24: =SUM('案件．要員情報'!V25:AA25) -> 0.23157895 | Q24: =SUM('案件．要員情報'!AB25:AG25) -> 0 | R24: =SUM('案件．要員情報'!AH25:AM25) -> 0 | S24: =SUM('案件．要員情報'!AN25:AS25) -> 0 | T24: =SUM('案件．要員情報'!AT25:AY25) -> 0 | U24: =SUM('案件．要員情報'!AZ25:BF25) -> 0 | V24: =SUM('案件．要員情報'!BG25:BN25) -> 0 | W24: =SUM('案件．要員情報'!BO25:BV25) -> 0 | X24: =SUM('案件．要員情報'!BW25:CD25) -> 0 | Y24: =SUM('案件．要員情報'!CE25:CL25) -> 0 | Z24: =SUM('案件．要員情報'!CM25:CT25) -> 0 | AA24: =SUM(O24:Z24) -> 1.0399123
N25: 実績 | O25: =SUM('案件．要員情報'!O26:U26) -> 0.775 | P25: =SUM('案件．要員情報'!V26:AA26) -> 0.16491228 | Q25: =SUM('案件．要員情報'!AB26:AG26) -> 0 | R25: =SUM('案件．要員情報'!AH26:AM26) -> 0 | S25: =SUM('案件．要員情報'!AN26:AS26) -> 0 | T25: =SUM('案件．要員情報'!AT26:AY26) -> 0 | U25: =SUM('案件．要員情報'!AZ26:BF26) -> 0 | V25: =SUM('案件．要員情報'!BG26:BN26) -> 0 | W25: =SUM('案件．要員情報'!BO26:BV26) -> 0 | X25: =SUM('案件．要員情報'!BW26:CD26) -> 0 | Y25: =SUM('案件．要員情報'!CE26:CL26) -> 0 | Z25: =SUM('案件．要員情報'!CM26:CT26) -> 0 | AA25: =SUM(O25:Z25) -> 0.93991228
A26: 11 | B26: 完了 | C26: その他 | D26: 坂野 | E26: EPM14 | G26: 【EPM】【依頼】レポーティング開発 | N26: 計画 | O26: =SUM('案件．要員情報'!O27:U27) -> 0.15 | P26: =SUM('案件．要員情報'!V27:AA27) -> 0 | Q26: =SUM('案件．要員情報'!AB27:AG27) -> 0 | R26: =SUM('案件．要員情報'!AH27:AM27) -> 0 | S26: =SUM('案件．要員情報'!AN27:AS27) -> 0 | T26: =SUM('案件．要員情報'!AT27:AY27) -> 0 | U26: =SUM('案件．要員情報'!AZ27:BF27) -> 0 | V26: =SUM('案件．要員情報'!BG27:BN27) -> 0 | W26: =SUM('案件．要員情報'!BO27:BV27) -> 0 | X26: =SUM('案件．要員情報'!BW27:CD27) -> 0 | Y26: =SUM('案件．要員情報'!CE27:CL27) -> 0 | Z26: =SUM('案件．要員情報'!CM27:CT27) -> 0 | AA26: =SUM(O26:Z26) -> 0.15
N27: 実績 | O27: =SUM('案件．要員情報'!O28:U28) -> 0.13333333 | P27: =SUM('案件．要員情報'!V28:AA28) -> 0 | Q27: =SUM('案件．要員情報'!AB28:AG28) -> 0 | R27: =SUM('案件．要員情報'!AH28:AM28) -> 0 | S27: =SUM('案件．要員情報'!AN28:AS28) -> 0 | T27: =SUM('案件．要員情報'!AT28:AY28) -> 0 | U27: =SUM('案件．要員情報'!AZ28:BF28) -> 0 | V27: =SUM('案件．要員情報'!BG28:BN28) -> 0 | W27: =SUM('案件．要員情報'!BO28:BV28) -> 0 | X27: =SUM('案件．要員情報'!BW28:CD28) -> 0 | Y27: =SUM('案件．要員情報'!CE28:CL28) -> 0 | Z27: =SUM('案件．要員情報'!CM28:CT28) -> 0 | AA27: =SUM(O27:Z27) -> 0.13333333
A28: 12 | B28: 完了 | C28: その他 | D28: 坂野 | E28: PA5 | G28: 【PLATE】PLATE AUTOマニュアル修正 | N28: 計画 | O28: =SUM('案件．要員情報'!O29:U29) -> 0.066666667 | P28: =SUM('案件．要員情報'!V29:AA29) -> 0 | Q28: =SUM('案件．要員情報'!AB29:AG29) -> 0 | R28: =SUM('案件．要員情報'!AH29:AM29) -> 0 | S28: =SUM('案件．要員情報'!AN29:AS29) -> 0 | T28: =SUM('案件．要員情報'!AT29:AY29) -> 0 | U28: =SUM('案件．要員情報'!AZ29:BF29) -> 0 | V28: =SUM('案件．要員情報'!BG29:BN29) -> 0 | W28: =SUM('案件．要員情報'!BO29:BV29) -> 0 | X28: =SUM('案件．要員情報'!BW29:CD29) -> 0 | Y28: =SUM('案件．要員情報'!CE29:CL29) -> 0 | Z28: =SUM('案件．要員情報'!CM29:CT29) -> 0 | AA28: =SUM(O28:Z28) -> 0.066666667
N29: 実績 | O29: =SUM('案件．要員情報'!O30:U30) -> 0.054166667 | P29: =SUM('案件．要員情報'!V30:AA30) -> 0 | Q29: =SUM('案件．要員情報'!AB30:AG30) -> 0 | R29: =SUM('案件．要員情報'!AH30:AM30) -> 0 | S29: =SUM('案件．要員情報'!AN30:AS30) -> 0 | T29: =SUM('案件．要員情報'!AT30:AY30) -> 0 | U29: =SUM('案件．要員情報'!AZ30:BF30) -> 0 | V29: =SUM('案件．要員情報'!BG30:BN30) -> 0 | W29: =SUM('案件．要員情報'!BO30:BV30) -> 0 | X29: =SUM('案件．要員情報'!BW30:CD30) -> 0 | Y29: =SUM('案件．要員情報'!CE30:CL30) -> 0 | Z29: =SUM('案件．要員情報'!CM30:CT30) -> 0 | AA29: =SUM(O29:Z29) -> 0.054166667
A30: 13 | B30: 完了 | C30: 定型 | D30: 山田 | E30: F205 | F30: PB00202097 | G30: PB00202097_【定型】加入協会名変更 | N30: 計画 | O30: =SUM('案件．要員情報'!O31:U31) -> 0.61666667 | P30: =SUM('案件．要員情報'!V31:AA31) -> 0 | Q30: =SUM('案件．要員情報'!AB31:AG31) -> 0 | R30: =SUM('案件．要員情報'!AH31:AM31) -> 0 | S30: =SUM('案件．要員情報'!AN31:AS31) -> 0 | T30: =SUM('案件．要員情報'!AT31:AY31) -> 0 | U30: =SUM('案件．要員情報'!AZ31:BF31) -> 0 | V30: =SUM('案件．要員情報'!BG31:BN31) -> 0 | W30: =SUM('案件．要員情報'!BO31:BV31) -> 0 | X30: =SUM('案件．要員情報'!BW31:CD31) -> 0 | Y30: =SUM('案件．要員情報'!CE31:CL31) -> 0 | Z30: =SUM('案件．要員情報'!CM31:CT31) -> 0 | AA30: =SUM(O30:Z30) -> 0.61666667
N31: 実績 | O31: =SUM('案件．要員情報'!O32:U32) -> 0.58541667 | P31: =SUM('案件．要員情報'!V32:AA32) -> 0 | Q31: =SUM('案件．要員情報'!AB32:AG32) -> 0 | R31: =SUM('案件．要員情報'!AH32:AM32) -> 0 | S31: =SUM('案件．要員情報'!AN32:AS32) -> 0 | T31: =SUM('案件．要員情報'!AT32:AY32) -> 0 | U31: =SUM('案件．要員情報'!AZ32:BF32) -> 0 | V31: =SUM('案件．要員情報'!BG32:BN32) -> 0 | W31: =SUM('案件．要員情報'!BO32:BV32) -> 0 | X31: =SUM('案件．要員情報'!BW32:CD32) -> 0 | Y31: =SUM('案件．要員情報'!CE32:CL32) -> 0 | Z31: =SUM('案件．要員情報'!CM32:CT32) -> 0 | AA31: =SUM(O31:Z31) -> 0.58541667
A32: 14 | B32: 完了 | C32: その他 | D32: 安藤 | E32: PR16 | F32: PBxxxxxxxx | G32: 【WB4】【開発依頼】4670_PBxxxxxxxx_(0D)管理者画面の表示修正 | N32: 計画 | O32: =SUM('案件．要員情報'!O33:U33) -> 0.35 | P32: =SUM('案件．要員情報'!V33:AA33) -> 0.63157895 | Q32: =SUM('案件．要員情報'!AB33:AG33) -> 0.060606061 | R32: =SUM('案件．要員情報'!AH33:AM33) -> 0 | S32: =SUM('案件．要員情報'!AN33:AS33) -> 0.038095238 | T32: =SUM('案件．要員情報'!AT33:AY33) -> 0 | U32: =SUM('案件．要員情報'!AZ33:BF33) -> 0 | V32: =SUM('案件．要員情報'!BG33:BN33) -> 0 | W32: =SUM('案件．要員情報'!BO33:BV33) -> 0 | X32: =SUM('案件．要員情報'!BW33:CD33) -> 0 | Y32: =SUM('案件．要員情報'!CE33:CL33) -> 0 | Z32: =SUM('案件．要員情報'!CM33:CT33) -> 0 | AA32: =SUM(O32:Z32) -> 1.0802802
N33: 実績 | O33: =SUM('案件．要員情報'!O34:U34) -> 0.31666667 | P33: =SUM('案件．要員情報'!V34:AA34) -> 0.62105263 | Q33: =SUM('案件．要員情報'!AB34:AG34) -> 0.036363636 | R33: =SUM('案件．要員情報'!AH34:AM34) -> 0 | S33: =SUM('案件．要員情報'!AN34:AS34) -> 0.033333333 | T33: =SUM('案件．要員情報'!AT34:AY34) -> 0 | U33: =SUM('案件．要員情報'!AZ34:BF34) -> 0 | V33: =SUM('案件．要員情報'!BG34:BN34) -> 0 | W33: =SUM('案件．要員情報'!BO34:BV34) -> 0 | X33: =SUM('案件．要員情報'!BW34:CD34) -> 0 | Y33: =SUM('案件．要員情報'!CE34:CL34) -> 0 | Z33: =SUM('案件．要員情報'!CM34:CT34) -> 0 | AA33: =SUM(O33:Z33) -> 1.0074163
A34: 15 | B34: 完了 | C34: その他 | D34: 髙木 | E34: WA5 | G34: 【見積依頼】【EPM2】J-IRISS運営終了に伴う内部者情報照合ツール改修 | N34: 計画 | O34: =SUM('案件．要員情報'!O35:U35) -> 0.0125 | P34: =SUM('案件．要員情報'!V35:AA35) -> 0 | Q34: =SUM('案件．要員情報'!AB35:AG35) -> 0 | R34: =SUM('案件．要員情報'!AH35:AM35) -> 0 | S34: =SUM('案件．要員情報'!AN35:AS35) -> 0 | T34: =SUM('案件．要員情報'!AT35:AY35) -> 0 | U34: =SUM('案件．要員情報'!AZ35:BF35) -> 0 | V34: =SUM('案件．要員情報'!BG35:BN35) -> 0 | W34: =SUM('案件．要員情報'!BO35:BV35) -> 0 | X34: =SUM('案件．要員情報'!BW35:CD35) -> 0 | Y34: =SUM('案件．要員情報'!CE35:CL35) -> 0 | Z34: =SUM('案件．要員情報'!CM35:CT35) -> 0 | AA34: =SUM(O34:Z34) -> 0.0125
N35: 実績 | O35: =SUM('案件．要員情報'!O36:U36) -> 0.0041666667 | P35: =SUM('案件．要員情報'!V36:AA36) -> 0 | Q35: =SUM('案件．要員情報'!AB36:AG36) -> 0 | R35: =SUM('案件．要員情報'!AH36:AM36) -> 0 | S35: =SUM('案件．要員情報'!AN36:AS36) -> 0 | T35: =SUM('案件．要員情報'!AT36:AY36) -> 0 | U35: =SUM('案件．要員情報'!AZ36:BF36) -> 0 | V35: =SUM('案件．要員情報'!BG36:BN36) -> 0 | W35: =SUM('案件．要員情報'!BO36:BV36) -> 0 | X35: =SUM('案件．要員情報'!BW36:CD36) -> 0 | Y35: =SUM('案件．要員情報'!CE36:CL36) -> 0 | Z35: =SUM('案件．要員情報'!CM36:CT36) -> 0 | AA35: =SUM(O35:Z35) -> 0.0041666667
A36: 16 | B36: 完了 | C36: その他 | D36: 髙木 | E36: PR17 | F36: PB00202057 | G36: 【見積依頼】4614_PB00202057_本人確認書類への「特定在留カード」等追加 | N36: 計画 | O36: =SUM('案件．要員情報'!O37:U37) -> 0 | P36: =SUM('案件．要員情報'!V37:AA37) -> 1.354386 | Q36: =SUM('案件．要員情報'!AB37:AG37) -> 0.75151515 | R36: =SUM('案件．要員情報'!AH37:AM37) -> 0 | S36: =SUM('案件．要員情報'!AN37:AS37) -> 0 | T36: =SUM('案件．要員情報'!AT37:AY37) -> 0 | U36: =SUM('案件．要員情報'!AZ37:BF37) -> 0 | V36: =SUM('案件．要員情報'!BG37:BN37) -> 0 | W36: =SUM('案件．要員情報'!BO37:BV37) -> 0 | X36: =SUM('案件．要員情報'!BW37:CD37) -> 0 | Y36: =SUM('案件．要員情報'!CE37:CL37) -> 0 | Z36: =SUM('案件．要員情報'!CM37:CT37) -> 0 | AA36: =SUM(O36:Z36) -> 2.1059011
N37: 実績 | O37: =SUM('案件．要員情報'!O38:U38) -> 0 | P37: =SUM('案件．要員情報'!V38:AA38) -> 1.2982456 | Q37: =SUM('案件．要員情報'!AB38:AG38) -> 0.70606061 | R37: =SUM('案件．要員情報'!AH38:AM38) -> 0 | S37: =SUM('案件．要員情報'!AN38:AS38) -> 0 | T37: =SUM('案件．要員情報'!AT38:AY38) -> 0 | U37: =SUM('案件．要員情報'!AZ38:BF38) -> 0 | V37: =SUM('案件．要員情報'!BG38:BN38) -> 0 | W37: =SUM('案件．要員情報'!BO38:BV38) -> 0 | X37: =SUM('案件．要員情報'!BW38:CD38) -> 0 | Y37: =SUM('案件．要員情報'!CE38:CL38) -> 0 | Z37: =SUM('案件．要員情報'!CM38:CT38) -> 0 | AA37: =SUM(O37:Z37) -> 2.0043062
A38: 17 | B38: 完了 | C38: その他 | D38: 仲井 | E38: BT8 | F38: PBxxxxxxxx | G38: 【WB4】【開発案件】4665_PBxxxxxxxx_(0D,46)不要な監視抑止対応 | N38: 計画 | O38: =SUM('案件．要員情報'!O39:U39) -> 0 | P38: =SUM('案件．要員情報'!V39:AA39) -> 0.50526316 | Q38: =SUM('案件．要員情報'!AB39:AG39) -> 0.40606061 | R38: =SUM('案件．要員情報'!AH39:AM39) -> 0.42424242 | S38: =SUM('案件．要員情報'!AN39:AS39) -> 0.0063492063 | T38: =SUM('案件．要員情報'!AT39:AY39) -> 0.13939394 | U38: =SUM('案件．要員情報'!AZ39:BF39) -> 0 | V38: =SUM('案件．要員情報'!BG39:BN39) -> 0 | W38: =SUM('案件．要員情報'!BO39:BV39) -> 0 | X38: =SUM('案件．要員情報'!BW39:CD39) -> 0 | Y38: =SUM('案件．要員情報'!CE39:CL39) -> 0 | Z38: =SUM('案件．要員情報'!CM39:CT39) -> 0 | AA38: =SUM(O38:Z38) -> 1.4813093
N39: 実績 | O39: =SUM('案件．要員情報'!O40:U40) -> 0 | P39: =SUM('案件．要員情報'!V40:AA40) -> 0.44912281 | Q39: =SUM('案件．要員情報'!AB40:AG40) -> 0.30606061 | R39: =SUM('案件．要員情報'!AH40:AM40) -> 0.40454545 | S39: =SUM('案件．要員情報'!AN40:AS40) -> 0.0031746032 | T39: =SUM('案件．要員情報'!AT40:AY40) -> 0.12121212 | U39: =SUM('案件．要員情報'!AZ40:BF40) -> 0 | V39: =SUM('案件．要員情報'!BG40:BN40) -> 0 | W39: =SUM('案件．要員情報'!BO40:BV40) -> 0 | X39: =SUM('案件．要員情報'!BW40:CD40) -> 0 | Y39: =SUM('案件．要員情報'!CE40:CL40) -> 0 | Z39: =SUM('案件．要員情報'!CM40:CT40) -> 0 | AA39: =SUM(O39:Z39) -> 1.2841156
A40: 18 | B40: 着手中 | C40: その他 | D40: 梶 | E40: SFA11 | G40: 【SFA】【開発依頼】0G_面談記録表（SFA）バージョンアップ対応 | N40: 計画 | O40: =SUM('案件．要員情報'!O41:U41) -> 0 | P40: =SUM('案件．要員情報'!V41:AA41) -> 0.54736842 | Q40: =SUM('案件．要員情報'!AB41:AG41) -> 1.6484848 | R40: =SUM('案件．要員情報'!AH41:AM41) -> 1.3757576 | S40: =SUM('案件．要員情報'!AN41:AS41) -> 1.752381 | T40: =SUM('案件．要員情報'!AT41:AY41) -> 1.0606061 | U40: =SUM('案件．要員情報'!AZ41:BF41) -> 0.18 | V40: =SUM('案件．要員情報'!BG41:BN41) -> 0 | W40: =SUM('案件．要員情報'!BO41:BV41) -> 0 | X40: =SUM('案件．要員情報'!BW41:CD41) -> 0 | Y40: =SUM('案件．要員情報'!CE41:CL41) -> 0 | Z40: =SUM('案件．要員情報'!CM41:CT41) -> 0 | AA40: =SUM(O40:Z40) -> 6.5645979
...

Sheet 案件．要員情報
A1: 案件．要員情報 | P1: Total Member - 7 | S1: Contract Member - 5 | W1: Total Member - 6 | Y1: Contract Member - 5 | AC1: Total Member - 6 | AE1: Contract Member - 5 | AI1: Total Member - 6 | AK1: Contract Member - 5 | AO1: Total Member - 6 | AQ1: Contract Member - 5 | AU1: Total Member - 6 | AW1: Contract Member - 5 | BA1: Total Member - 7 | BC1: Contract Member - 5 | BH1: Total Member - 8 | BK1: Contract Member - 7 | BP1: Total Member - 8 | BS1: Contract Member - 7 | BX1: Total Member - 8 | CA1: Contract Member - 7 | CF1: Total Member - 8 | CI1: Contract Member - 7 | CN1: Total Member - 8 | CQ1: Contract Member - 7
P2: FOC Member - 2 | W2: FOC Member - 1 | AC2: FOC Member - 1 | AI2: FOC Member - 1 | AO2: FOC Member - 1 | AU2: FOC Member - 1 | BA2: FOC Member - 2 | BH2: FOC Member - 1 | BP2: FOC Member - 1 | BX2: FOC Member - 1 | CF2: FOC Member - 1 | CN2: FOC Member - 1
A3: ■案件
A4: No. | B4: ステータス | C4: 区分 | D4: DIR 担当 | E4: 案件管理コード（DAT) | F4: 案件管理コード（DIR) | G4: 案件 | H4: 計画 (DIR) | I4: 計画 (DAT) | J4: 進捗 （％） | K4: 着手日 | L4: 完了日 | M4: 備考 | N4: 工数（人月）
N5: 4月 | V5: 5月 | AB5: 6月 | AH5: 7月 | AN5: 8月 | AT5: 9月 | AZ5: 10月 | BG5: 11月 | BO5: 12月 | BW5: 1月 | CE5: 2月 | CM5: 3月
O6: TZA | P6: AMTZ | Q6: TSO | R6: NCM | S6: MMH | T6: SMZK | U6: SYA | V6: TZA | W6: AMTZ | X6: TSO | Y6: MMH | Z6: SMZK | AA6: SYA | AB6: TZA | AC6: AMTZ | AD6: TSO | AE6: MMH | AF6: SMZK | AG6: SYA | AH6: TZA | AI6: AMTZ | AJ6: TSO | AK6: MMH | AL6: SMZK | AM6: SYA | AN6: TZA | AO6: AMTZ | AP6: TSO | AQ6: MMH | AR6: SMZK | AS6: SYA | AT6: TZA | AU6: AMTZ | AV6: TSO | AW6: MMH | AX6: SMZK | AY6: SYA | AZ6: TZA | BA6: AMTZ | BB6: TSO | BC6: MMH | BD6: SMZK | BE6: SYA | BF6: MMM | BG6: TZA | BH6: HWY | BI6: SPH | BJ6: KSH | BK6: TSO | BL6: SNNT | BM6: IKK | BN6: KBN | BO6: TZA | BP6: HWY | BQ6: SPH | BR6: KSH | BS6: TSO | BT6: SNNT | BU6: IKK | BV6: KBN | BW6: TZA | BX6: HWY | BY6: SPH | BZ6: KSH | CA6: TSO | CB6: SNNT | CC6: IKK | CD6: KBN | CE6: TZA | CF6: HWY | CG6: SPH | CH6: KSH | CI6: TSO | CJ6: SNNT | CK6: IKK | CL6: KBN | CM6: TZA | CN6: HWY | CO6: SPH | CP6: KSH | CQ6: TSO | CR6: SNNT | CS6: IKK | CT6: KBN
A7: 1 | B7: 着手中 | C7: その他 | D7: 飯田 | E7: BW1 | F7: A5207110 | G7: 【案件依頼】ビルド作業を対応 | H7: =SUM(AZ7:BF7) -> 0.33333333 | I7: =SUM(AZ8:BF8) -> 0.06 | N7: 計画 | O7: =(0)/120 -> 0 | P7: =(0)/120 -> 0 | Q7: =(15)/120 -> 0.125 | R7: =(12.5)/120 -> 0.10416667 | S7: =(12.5)/120 -> 0.10416667 | T7: =(15)/120 -> 0.125 | U7: =(0)/120 -> 0 | V7: =(0)/142.5 -> 0 | W7: =(0)/142.5 -> 0 | X7: =(10)/142.5 -> 0.070175439 | Y7: =(0)/142.5 -> 0 | Z7: =(10)/142.5 -> 0.070175439 | AA7: =(10)/142.5 -> 0.070175439 | AB7: =(0)/165 -> 0 | AC7: =(0)/165 -> 0 | AD7: =(10)/165 -> 0.060606061 | AE7: =(15)/165 -> 0.090909091 | AF7: =(5)/165 -> 0.03030303 | AG7: =(15)/165 -> 0.090909091 | AH7: =(0)/165 -> 0 | AI7: =(0)/165 -> 0 | AJ7: =(0)/165 -> 0 | AK7: =(10)/165 -> 0.060606061 | AL7: =(3)/165 -> 0.018181818 | AM7: =(7)/165 -> 0.042424242 | AN7: =(0)/157.5 -> 0 | AO7: =(10)/157.5 -> 0.063492063 | AP7: =(20)/157.5 -> 0.12698413 | AQ7: =(0)/157.5 -> 0 | AR7: =(0)/157.5 -> 0 | AS7: =(3)/157.5 -> 0.019047619 | AT7: =(0)/165 -> 0 | AU7: =(10)/165 -> 0.060606061 | AV7: =(11.5)/165 -> 0.06969697 | AW7: =(11.5)/165 -> 0.06969697 | AX7: =(10)/165 -> 0.060606061 | AY7: =(10)/165 -> 0.060606061 | AZ7: =(0)/150 -> 0 | BA7: =(10)/150 -> 0.066666667 | BB7: =(10)/150 -> 0.066666667 | BC7: =(10)/150 -> 0.066666667 | BD7: =(10)/150 -> 0.066666667 | BE7: =(10)/150 -> 0.066666667 | BF7: =(0)/150 -> 0 | BG7: =0/142.5 -> 0 | BH7: =0/142.5 -> 0 | BI7: =0/142.5 -> 0 | BJ7: =0/142.5 -> 0 | BK7: =0/142.5 -> 0 | BL7: =0/172.5 -> 0 | BM7: =0/172.5 -> 0 | BN7: =0/172.5 -> 0 | BO7: =0/157.5 -> 0 | BP7: =0/157.5 -> 0 | BQ7: =0/157.5 -> 0 | BR7: =0/157.5 -> 0 | BS7: =0/157.5 -> 0 | BT7: =0/172.5 -> 0 | BU7: =0/172.5 -> 0 | BV7: =0/172.5 -> 0 | BW7: =0/157.5 -> 0 | BX7: =0/157.5 -> 0 | BY7: =0/157.5 -> 0 | BZ7: =0/157.5 -> 0 | CA7: =0/157.5 -> 0 | CB7: =0/172.5 -> 0 | CC7: =0/172.5 -> 0 | CD7: =0/172.5 -> 0 | CE7: =0/157.5 -> 0 | CF7: =0/157.5 -> 0 | CG7: =0/157.5 -> 0 | CH7: =0/157.5 -> 0 | CI7: =0/157.5 -> 0 | CJ7: =0/172.5 -> 0 | CK7: =0/172.5 -> 0 | CL7: =0/172.5 -> 0 | CM7: =0/142.5 -> 0 | CN7: =0/142.5 -> 0 | CO7: =0/142.5 -> 0 | CP7: =0/142.5 -> 0 | CQ7: =0/142.5 -> 0 | CR7: =0/172.5 -> 0 | CS7: =0/172.5 -> 0 | CT7: =0/172.5 -> 0
N8: 実績 | O8: =(0)/120 -> 0 | P8: =(0)/120 -> 0 | Q8: =(2+4)/120 -> 0.05 | R8: =(0+6+4)/120 -> 0.083333333 | S8: =(0+6)/120 -> 0.05 | T8: =(2+4+7+4)/120 -> 0.14166667 | U8: =(0+10)/120 -> 0.083333333 | V8: =(0)/142.5 -> 0 | W8: =(0)/142.5 -> 0 | X8: =(0+6+4+2+1)/142.5 -> 0.09122807 | Y8: =(0)/142.5 -> 0 | Z8: =(0+6+2)/142.5 -> 0.056140351 | AA8: =(0+3+2+2)/142.5 -> 0.049122807 | AB8: =(0)/165 -> 0 | AC8: =(0+6+4)/165 -> 0.060606061 | AD8: =(0+6+1)/165 -> 0.042424242 | AE8: =(6+4)/165 -> 0.060606061 | AF8: =(0+2.5)/165 -> 0.015151515 | AG8: =(9+2+3)/165 -> 0.084848485 | AH8: =(0)/165 -> 0 | AI8: =(0)/165 -> 0 | AJ8: =(0)/165 -> 0 | AK8: =(1.5+2.5+6)/165 -> 0.060606061 | AL8: =(1.5+1)/165 -> 0.015151515 | AM8: =(3+4)/165 -> 0.042424242 | AN8: =(0)/157.5 -> 0 | AO8: =(6+4)/157.5 -> 0.063492063 | AP8: =(6+2+4+4)/157.5 -> 0.1015873 | AQ8: =(0+2)/157.5 -> 0.012698413 | AR8: =(0+2+2)/157.5 -> 0.025396825 | AS8: =(0+1)/157.5 -> 0.0063492063 | AT8: =(0)/165 -> 0 | AU8: =(6+4)/165 -> 0.060606061 | AV8: =(6+4+2)/165 -> 0.072727273 | AW8: =(4+4+4)/165 -> 0.072727273 | AX8: =(0+6)/165 -> 0.036363636 | AY8: =(4+4+1)/165 -> 0.054545455 | AZ8: =(0)/150 -> 0 | BA8: =(0)/150 -> 0 | BB8: =(0)/150 -> 0 | BC8: =(4)/150 -> 0.026666667 | BD8: =(5)/150 -> 0.033333333 | BE8: =(0)/150 -> 0 | BF8: =(0)/150 -> 0 | BG8: =0/142.5 -> 0 | BH8: =0/142.5 -> 0 | BI8: =0/142.5 -> 0 | BJ8: =0/142.5 -> 0 | BK8: =0/142.5 -> 0 | BL8: =0/172.5 -> 0 | BM8: =0/172.5 -> 0 | BN8: =0/172.5 -> 0 | BO8: =0/157.5 -> 0 | BP8: =0/157.5 -> 0 | BQ8: =0/157.5 -> 0 | BR8: =0/157.5 -> 0 | BS8: =0/157.5 -> 0 | BT8: =0/172.5 -> 0 | BU8: =0/172.5 -> 0 | BV8: =0/172.5 -> 0 | BW8: =0/157.5 -> 0 | BX8: =0/157.5 -> 0 | BY8: =0/157.5 -> 0 | BZ8: =0/157.5 -> 0 | CA8: =0/157.5 -> 0 | CB8: =0/172.5 -> 0 | CC8: =0/172.5 -> 0 | CD8: =0/172.5 -> 0 | CE8: =0/157.5 -> 0 | CF8: =0/157.5 -> 0 | CG8: =0/157.5 -> 0 | CH8: =0/157.5 -> 0 | CI8: =0/157.5 -> 0 | CJ8: =0/172.5 -> 0 | CK8: =0/172.5 -> 0 | CL8: =0/172.5 -> 0 | CM8: =0/142.5 -> 0 | CN8: =0/142.5 -> 0 | CO8: =0/142.5 -> 0 | CP8: =0/142.5 -> 0 | CQ8: =0/142.5 -> 0 | CR8: =0/172.5 -> 0 | CS8: =0/172.5 -> 0 | CT8: =0/172.5 -> 0
A9: 2 | B9: 完了 | C9: その他 | D9: 山本 | E9: WA2 | G9: 【開発依頼】作業の自動化_UATヘルスチェック | H9: =SUM(V9:AA9) -> 0 | I9: =SUM(V10:AA10) -> 0 | N9: 計画 | O9: =(2.5)/120 -> 0.020833333 | P9: =(0)/120 -> 0 | Q9: =(2.5)/120 -> 0.020833333 | R9: =(0)/120 -> 0 | S9: =(0)/120 -> 0 | T9: =(0)/120 -> 0 | U9: =(0)/120 -> 0 | V9: =(0)/142.5 -> 0 | W9: =(0)/142.5 -> 0 | X9: =(0)/142.5 -> 0 | Y9: =(0)/142.5 -> 0 | Z9: =(0)/142.5 -> 0 | AA9: =(0)/142.5 -> 0 | AB9: =0/165 -> 0 | AC9: =0/165 -> 0 | AD9: =0/165 -> 0 | AE9: =0/165 -> 0 | AF9: =0/165 -> 0 | AG9: =0/165 -> 0 | AH9: =(0)/165 -> 0 | AI9: =(0)/165 -> 0 | AJ9: =(0)/165 -> 0 | AK9: =(0)/165 -> 0 | AL9: =(0)/165 -> 0 | AM9: =(0)/165 -> 0 | AN9: =0/157.5 -> 0 | AO9: =0/157.5 -> 0 | AP9: =0/157.5 -> 0 | AQ9: =0/157.5 -> 0 | AR9: =0/157.5 -> 0 | AS9: =0/165 -> 0 | AT9: =0/172.5 -> 0 | AU9: =0/172.5 -> 0 | AV9: =0/172.5 -> 0 | AW9: =0/172.5 -> 0 | AX9: =0/172.5 -> 0 | AY9: =0/172.5 -> 0 | AZ9: =0/142.5 -> 0 | BA9: =0/142.5 -> 0 | BB9: =0/142.5 -> 0 | BC9: =0/142.5 -> 0 | BD9: =0/142.5 -> 0 | BE9: =0/172.5 -> 0 | BF9: =0/172.5 -> 0 | BG9: =0/142.5 -> 0 | BH9: =0/142.5 -> 0 | BI9: =0/142.5 -> 0 | BJ9: =0/142.5 -> 0 | BK9: =0/142.5 -> 0 | BL9: =0/172.5 -> 0 | BM9: =0/172.5 -> 0 | BN9: =0/172.5 -> 0 | BO9: =0/157.5 -> 0 | BP9: =0/157.5 -> 0 | BQ9: =0/157.5 -> 0 | BR9: =0/157.5 -> 0 | BS9: =0/157.5 -> 0 | BT9: =0/172.5 -> 0 | BU9: =0/172.5 -> 0 | BV9: =0/172.5 -> 0 | BW9: =0/157.5 -> 0 | BX9: =0/157.5 -> 0 | BY9: =0/157.5 -> 0 | BZ9: =0/157.5 -> 0 | CA9: =0/157.5 -> 0 | CB9: =0/172.5 -> 0 | CC9: =0/172.5 -> 0 | CD9: =0/172.5 -> 0 | CE9: =0/157.5 -> 0 | CF9: =0/157.5 -> 0 | CG9: =0/157.5 -> 0 | CH9: =0/157.5 -> 0 | CI9: =0/157.5 -> 0 | CJ9: =0/172.5 -> 0 | CK9: =0/172.5 -> 0 | CL9: =0/172.5 -> 0 | CM9: =0/142.5 -> 0 | CN9: =0/142.5 -> 0 | CO9: =0/142.5 -> 0 | CP9: =0/142.5 -> 0 | CQ9: =0/142.5 -> 0 | CR9: =0/172.5 -> 0 | CS9: =0/172.5 -> 0 | CT9: =0/172.5 -> 0
N10: 実績 | O10: =(1+1)/120 -> 0.016666667 | P10: =(0)/120 -> 0 | Q10: =(1+0.5)/120 -> 0.0125 | R10: =(0)/120 -> 0 | S10: =(0)/120 -> 0 | T10: =(0)/120 -> 0 | U10: =(0)/120 -> 0 | V10: =(0)/142.5 -> 0 | W10: =(0)/142.5 -> 0 | X10: =(0)/142.5 -> 0 | Y10: =(0)/142.5 -> 0 | Z10: =(0)/142.5 -> 0 | AA10: =(0)/142.5 -> 0 | AB10: =0/165 -> 0 | AC10: =0/165 -> 0 | AD10: =0/165 -> 0 | AE10: =0/165 -> 0 | AF10: =0/165 -> 0 | AG10: =0/165 -> 0 | AH10: =(0)/165 -> 0 | AI10: =(0)/165 -> 0 | AJ10: =(0)/165 -> 0 | AK10: =(0)/165 -> 0 | AL10: =(0)/165 -> 0 | AM10: =(0)/165 -> 0 | AN10: =0/157.5 -> 0 | AO10: =0/157.5 -> 0 | AP10: =0/157.5 -> 0 | AQ10: =0/157.5 -> 0 | AR10: =0/157.5 -> 0 | AS10: =0/165 -> 0 | AT10: =0/172.5 -> 0 | AU10: =0/172.5 -> 0 | AV10: =0/172.5 -> 0 | AW10: =0/172.5 -> 0 | AX10: =0/172.5 -> 0 | AY10: =0/172.5 -> 0 | AZ10: =0/142.5 -> 0 | BA10: =0/142.5 -> 0 | BB10: =0/142.5 -> 0 | BC10: =0/142.5 -> 0 | BD10: =0/142.5 -> 0 | BE10: =0/172.5 -> 0 | BF10: =0/172.5 -> 0 | BG10: =0/142.5 -> 0 | BH10: =0/142.5 -> 0 | BI10: =0/142.5 -> 0 | BJ10: =0/142.5 -> 0 | BK10: =0/142.5 -> 0 | BL10: =0/172.5 -> 0 | BM10: =0/172.5 -> 0 | BN10: =0/172.5 -> 0 | BO10: =0/157.5 -> 0 | BP10: =0/157.5 -> 0 | BQ10: =0/157.5 -> 0 | BR10: =0/157.5 -> 0 | BS10: =0/157.5 -> 0 | BT10: =0/172.5 -> 0 | BU10: =0/172.5 -> 0 | BV10: =0/172.5 -> 0 | BW10: =0/157.5 -> 0 | BX10: =0/157.5 -> 0 | BY10: =0/157.5 -> 0 | BZ10: =0/157.5 -> 0 | CA10: =0/157.5 -> 0 | CB10: =0/172.5 -> 0 | CC10: =0/172.5 -> 0 | CD10: =0/172.5 -> 0 | CE10: =0/157.5 -> 0 | CF10: =0/157.5 -> 0 | CG10: =0/157.5 -> 0 | CH10: =0/157.5 -> 0 | CI10: =0/157.5 -> 0 | CJ10: =0/172.5 -> 0 | CK10: =0/172.5 -> 0 | CL10: =0/172.5 -> 0 | CM10: =0/142.5 -> 0 | CN10: =0/142.5 -> 0 | CO10: =0/142.5 -> 0 | CP10: =0/142.5 -> 0 | CQ10: =0/142.5 -> 0 | CR10: =0/172.5 -> 0 | CS10: =0/172.5 -> 0 | CT10: =0/172.5 -> 0
A11: 3 | B11: 完了 | C11: その他 | D11: 仲井 | E11: WA6 | F11: PBxxxxxxxx | G11: 【開発依頼】作業の自動化・効率化_エラーメッセージ一覧作成 | H11: =SUM(V11:AA11) -> 0 | I11: =SUM(V12:AA12) -> 0 | N11: 計画 | O11: =(4)/120 -> 0.033333333 | P11: =(0)/120 -> 0 | Q11: =(38)/120 -> 0.31666667 | R11: =(0)/120 -> 0 | S11: =(0)/120 -> 0 | T11: =(0)/120 -> 0 | U11: =(38)/120 -> 0.31666667 | V11: =(0)/142.5 -> 0 | W11: =(0)/142.5 -> 0 | X11: =(0)/142.5 -> 0 | Y11: =(0)/142.5 -> 0 | Z11: =(0)/142.5 -> 0 | AA11: =(0)/142.5 -> 0 | AB11: =0/165 -> 0 | AC11: =0/165 -> 0 | AD11: =0/165 -> 0 | AE11: =0/165 -> 0 | AF11: =0/165 -> 0 | AG11: =0/165 -> 0 | AH11: =(0)/165 -> 0 | AI11: =(0)/165 -> 0 | AJ11: =(0)/165 -> 0 | AK11: =(0)/165 -> 0 | AL11: =(0)/165 -> 0 | AM11: =(0)/165 -> 0 | AN11: =0/157.5 -> 0 | AO11: =0/157.5 -> 0 | AP11: =0/157.5 -> 0 | AQ11: =0/157.5 -> 0 | AR11: =0/157.5 -> 0 | AS11: =0/165 -> 0 | AT11: =0/172.5 -> 0 | AU11: =0/172.5 -> 0 | AV11: =0/172.5 -> 0 | AW11: =0/172.5 -> 0 | AX11: =0/172.5 -> 0 | AY11: =0/172.5 -> 0 | AZ11: =0/142.5 -> 0 | BA11: =0/142.5 -> 0 | BB11: =0/142.5 -> 0 | BC11: =0/142.5 -> 0 | BD11: =0/142.5 -> 0 | BE11: =0/172.5 -> 0 | BF11: =0/172.5 -> 0 | BG11: =0/142.5 -> 0 | BH11: =0/142.5 -> 0 | BI11: =0/142.5 -> 0 | BJ11: =0/142.5 -> 0 | BK11: =0/142.5 -> 0 | BL11: =0/172.5 -> 0 | BM11: =0/172.5 -> 0 | BN11: =0/172.5 -> 0 | BO11: =0/157.5 -> 0 | BP11: =0/157.5 -> 0 | BQ11: =0/157.5 -> 0 | BR11: =0/157.5 -> 0 | BS11: =0/157.5 -> 0 | BT11: =0/172.5 -> 0 | BU11: =0/172.5 -> 0 | BV11: =0/172.5 -> 0 | BW11: =0/157.5 -> 0 | BX11: =0/157.5 -> 0 | BY11: =0/157.5 -> 0 | BZ11: =0/157.5 -> 0 | CA11: =0/157.5 -> 0 | CB11: =0/172.5 -> 0 | CC11: =0/172.5 -> 0 | CD11: =0/172.5 -> 0 | CE11: =0/157.5 -> 0 | CF11: =0/157.5 -> 0 | CG11: =0/157.5 -> 0 | CH11: =0/157.5 -> 0 | CI11: =0/157.5 -> 0 | CJ11: =0/172.5 -> 0 | CK11: =0/172.5 -> 0 | CL11: =0/172.5 -> 0 | CM11: =0/142.5 -> 0 | CN11: =0/142.5 -> 0 | CO11: =0/142.5 -> 0 | CP11: =0/142.5 -> 0 | CQ11: =0/142.5 -> 0 | CR11: =0/172.5 -> 0 | CS11: =0/172.5 -> 0 | CT11: =0/172.5 -> 0
N12: 実績 | O12: =(0+1)/120 -> 0.0083333333 | P12: =(0)/120 -> 0 | Q12: =(3+20+14)/120 -> 0.30833333 | R12: =(0)/120 -> 0 | S12: =(0)/120 -> 0 | T12: =(0)/120 -> 0 | U12: =(3.5+19.5+13)/120 -> 0.3 | V12: =(0)/142.5 -> 0 | W12: =(0)/142.5 -> 0 | X12: =(0)/142.5 -> 0 | Y12: =(0)/142.5 -> 0 | Z12: =(0)/142.5 -> 0 | AA12: =(0)/142.5 -> 0 | AB12: =0/165 -> 0 | AC12: =0/165 -> 0 | AD12: =0/165 -> 0 | AE12: =0/165 -> 0 | AF12: =0/165 -> 0 | AG12: =0/165 -> 0 | AH12: =(0)/165 -> 0 | AI12: =(0)/165 -> 0 | AJ12: =(0)/165 -> 0 | AK12: =(0)/165 -> 0 | AL12: =(0)/165 -> 0 | AM12: =(0)/165 -> 0 | AN12: =0/157.5 -> 0 | AO12: =0/157.5 -> 0 | AP12: =0/157.5 -> 0 | AQ12: =0/157.5 -> 0 | AR12: =0/157.5 -> 0 | AS12: =0/165 -> 0 | AT12: =0/172.5 -> 0 | AU12: =0/172.5 -> 0 | AV12: =0/172.5 -> 0 | AW12: =0/172.5 -> 0 | AX12: =0/172.5 -> 0 | AY12: =0/172.5 -> 0 | AZ12: =0/142.5 -> 0 | BA12: =0/142.5 -> 0 | BB12: =0/142.5 -> 0 | BC12: =0/142.5 -> 0 | BD12: =0/142.5 -> 0 | BE12: =0/172.5 -> 0 | BF12: =0/172.5 -> 0 | BG12: =0/142.5 -> 0 | BH12: =0/142.5 -> 0 | BI12: =0/142.5 -> 0 | BJ12: =0/142.5 -> 0 | BK12: =0/142.5 -> 0 | BL12: =0/172.5 -> 0 | BM12: =0/172.5 -> 0 | BN12: =0/172.5 -> 0 | BO12: =0/157.5 -> 0 | BP12: =0/157.5 -> 0 | BQ12: =0/157.5 -> 0 | BR12: =0/157.5 -> 0 | BS12: =0/157.5 -> 0 | BT12: =0/172.5 -> 0 | BU12: =0/172.5 -> 0 | BV12: =0/172.5 -> 0 | BW12: =0/157.5 -> 0 | BX12: =0/157.5 -> 0 | BY12: =0/157.5 -> 0 | BZ12: =0/157.5 -> 0 | CA12: =0/157.5 -> 0 | CB12: =0/172.5 -> 0 | CC12: =0/172.5 -> 0 | CD12: =0/172.5 -> 0 | CE12: =0/157.5 -> 0 | CF12: =0/157.5 -> 0 | CG12: =0/157.5 -> 0 | CH12: =0/157.5 -> 0 | CI12: =0/157.5 -> 0 | CJ12: =0/172.5 -> 0 | CK12: =0/172.5 -> 0 | CL12: =0/172.5 -> 0 | CM12: =0/142.5 -> 0 | CN12: =0/142.5 -> 0 | CO12: =0/142.5 -> 0 | CP12: =0/142.5 -> 0 | CQ12: =0/142.5 -> 0 | CR12: =0/172.5 -> 0 | CS12: =0/172.5 -> 0 | CT12: =0/172.5 -> 0
A13: 4 | B13: 完了 | C13: その他 | D13: 安藤 | E13: BT7 | F13: PBxxxxxxxx | G13: 【開発依頼】4631_PBxxxxxxxx_(90)バッチ機DISC使用率軽減対応 | H13: =SUM(AZ13:BF13) -> 0 | I13: =SUM(AZ14:BF14) -> 0 | N13: 計画 | O13: =(5)/120 -> 0.041666667 | P13: =(0)/120 -> 0 | Q13: =(0)/120 -> 0 | R13: =(35)/120 -> 0.29166667 | S13: =(30)/120 -> 0.25 | T13: =(0)/120 -> 0 | U13: =(0)/120 -> 0 | V13: =(0)/142.5 -> 0 | W13: =(0)/142.5 -> 0 | X13: =(0)/142.5 -> 0 | Y13: =(0)/142.5 -> 0 | Z13: =(0)/142.5 -> 0 | AA13: =(0)/142.5 -> 0 | AB13: =(5)/165 -> 0.03030303 | AC13: =(0)/165 -> 0 | AD13: =(20)/165 -> 0.12121212 | AE13: =(0)/165 -> 0 | AF13: =(0)/165 -> 0 | AG13: =(25)/165 -> 0.15151515 | AH13: =(0)/165 -> 0 | AI13: =(0)/165 -> 0 | AJ13: =(0)/165 -> 0 | AK13: =(0)/165 -> 0 | AL13: =(0)/165 -> 0 | AM13: =(0)/165 -> 0 | AN13: =0/157.5 -> 0 | AO13: =0/157.5 -> 0 | AP13: =0/157.5 -> 0 | AQ13: =0/157.5 -> 0 | AR13: =0/157.5 -> 0 | AS13: =0/165 -> 0 | AT13: =(2)/165 -> 0.012121212 | AU13: =(0)/165 -> 0 | AV13: =(10)/165 -> 0.060606061 | AW13: =(0)/165 -> 0 | AX13: =(0)/165 -> 0 | AY13: =(10)/165 -> 0.060606061 | AZ13: =(0)/150 -> 0 | BA13: =(0)/150 -> 0 | BB13: =(0)/150 -> 0 | BC13: =(0)/150 -> 0 | BD13: =(0)/150 -> 0 | BE13: =(0)/150 -> 0 | BF13: =(0)/150 -> 0 | BG13: =0/142.5 -> 0 | BH13: =0/142.5 -> 0 | BI13: =0/142.5 -> 0 | BJ13: =0/142.5 -> 0 | BK13: =0/142.5 -> 0 | BL13: =0/172.5 -> 0 | BM13: =0/172.5 -> 0 | BN13: =0/172.5 -> 0 | BO13: =0/157.5 -> 0 | BP13: =0/157.5 -> 0 | BQ13: =0/157.5 -> 0 | BR13: =0/157.5 -> 0 | BS13: =0/157.5 -> 0 | BT13: =0/172.5 -> 0 | BU13: =0/172.5 -> 0 | BV13: =0/172.5 -> 0 | BW13: =0/157.5 -> 0 | BX13: =0/157.5 -> 0 | BY13: =0/157.5 -> 0 | BZ13: =0/157.5 -> 0 | CA13: =0/157.5 -> 0 | CB13: =0/172.5 -> 0 | CC13: =0/172.5 -> 0 | CD13: =0/172.5 -> 0 | CE13: =0/157.5 -> 0 | CF13: =0/157.5 -> 0 | CG13: =0/157.5 -> 0 | CH13: =0/157.5 -> 0 | CI13: =0/157.5 -> 0 | CJ13: =0/172.5 -> 0 | CK13: =0/172.5 -> 0 | CL13: =0/172.5 -> 0 | CM13: =0/142.5 -> 0 | CN13: =0/142.5 -> 0 | CO13: =0/142.5 -> 0 | CP13: =0/142.5 -> 0 | CQ13: =0/142.5 -> 0 | CR13: =0/172.5 -> 0 | CS13: =0/172.5 -> 0 | CT13: =0/172.5 -> 0
N14: 実績 | O14: =(1.5+2+1+1.25)/120 -> 0.047916667 | P14: =(0)/120 -> 0 | Q14: =(0)/120 -> 0 | R14: =(3.5+15.5+7.5+7.5)/120 -> 0.28333333 | S14: =(7+3.5+11.5+4)/120 -> 0.21666667 | T14: =(0)/120 -> 0 | U14: =(0)/120 -> 0 | V14: =(0)/142.5 -> 0 | W14: =(0)/142.5 -> 0 | X14: =(0)/142.5 -> 0 | Y14: =(0)/142.5 -> 0 | Z14: =(0)/142.5 -> 0 | AA14: =(0)/142.5 -> 0 | AB14: =(1+2+1+1+0.5)/165 -> 0.033333333 | AC14: =(0)/165 -> 0 | AD14: =(1+16.5)/165 -> 0.10606061 | AE14: =(0)/165 -> 0 | AF14: =(0)/165 -> 0 | AG14: =(2+9.5+9)/165 -> 0.12424242 | AH14: =(0)/165 -> 0 | AI14: =(0)/165 -> 0 | AJ14: =(0)/165 -> 0 | AK14: =(0)/165 -> 0 | AL14: =(0)/165 -> 0 | AM14: =(0)/165 -> 0 | AN14: =0/157.5 -> 0 | AO14: =0/157.5 -> 0 | AP14: =0/157.5 -> 0 | AQ14: =0/157.5 -> 0 | AR14: =0/157.5 -> 0 | AS14: =0/165 -> 0 | AT14: =(0.5+1.5)/165 -> 0.012121212 | AU14: =(0)/165 -> 0 | AV14: =(7.25+2.5)/165 -> 0.059090909 | AW14: =(0)/165 -> 0 | AX14: =(0)/165 -> 0 | AY14: =(0+8.75)/165 -> 0.053030303 | AZ14: =(0)/150 -> 0 | BA14: =(0)/150 -> 0 | BB14: =(0)/150 -> 0 | BC14: =(0)/150 -> 0 | BD14: =(0)/150 -> 0 | BE14: =(0)/150 -> 0 | BF14: =(0)/150 -> 0 | BG14: =0/142.5 -> 0 | BH14: =0/142.5 -> 0 | BI14: =0/142.5 -> 0 | BJ14: =0/142.5 -> 0 | BK14: =0/142.5 -> 0 | BL14: =0/172.5 -> 0 | BM14: =0/172.5 -> 0 | BN14: =0/172.5 -> 0 | BO14: =0/157.5 -> 0 | BP14: =0/157.5 -> 0 | BQ14: =0/157.5 -> 0 | BR14: =0/157.5 -> 0 | BS14: =0/157.5 -> 0 | BT14: =0/172.5 -> 0 | BU14: =0/172.5 -> 0 | BV14: =0/172.5 -> 0 | BW14: =0/157.5 -> 0 | BX14: =0/157.5 -> 0 | BY14: =0/157.5 -> 0 | BZ14: =0/157.5 -> 0 | CA14: =0/157.5 -> 0 | CB14: =0/172.5 -> 0 | CC14: =0/172.5 -> 0 | CD14: =0/172.5 -> 0 | CE14: =0/157.5 -> 0 | CF14: =0/157.5 -> 0 | CG14: =0/157.5 -> 0 | CH14: =0/157.5 -> 0 | CI14: =0/157.5 -> 0 | CJ14: =0/172.5 -> 0 | CK14: =0/172.5 -> 0 | CL14: =0/172.5 -> 0 | CM14: =0/142.5 -> 0 | CN14: =0/142.5 -> 0 | CO14: =0/142.5 -> 0 | CP14: =0/142.5 -> 0 | CQ14: =0/142.5 -> 0 | CR14: =0/172.5 -> 0 | CS14: =0/172.5 -> 0 | CT14: =0/172.5 -> 0
A15: 5 | B15: 着手中 | C15: 定型 | D15: 山田 | E15: F201 | F15: PB00202063 | G15: 【定型】信用取引金利優遇条件設定依頼 | H15: =SUM(AZ15:BF15) -> 0 | I15: =SUM(AZ16:BF16) -> 0 | N15: 計画 | O15: =(5)/120 -> 0.041666667 | P15: =(0)/120 -> 0 | Q15: =(0)/120 -> 0 | R15: =(0)/120 -> 0 | S15: =(15)/120 -> 0.125 | T15: =(25)/120 -> 0.20833333 | U15: =(0)/120 -> 0 | V15: =(0)/142.5 -> 0 | W15: =(0)/142.5 -> 0 | X15: =(0)/142.5 -> 0 | Y15: =(0)/142.5 -> 0 | Z15: =(0)/142.5 -> 0 | AA15: =(0)/142.5 -> 0 | AB15: =0/165 -> 0 | AC15: =0/165 -> 0 | AD15: =0/165 -> 0 | AE15: =0/165 -> 0 | AF15: =0/165 -> 0 | AG15: =0/165 -> 0 | AH15: =(0)/165 -> 0 | AI15: =(0)/165 -> 0 | AJ15: =(0)/165 -> 0 | AK15: =(0)/165 -> 0 | AL15: =(0)/165 -> 0 | AM15: =(0)/165 -> 0 | AN15: =0/157.5 -> 0 | AO15: =0/157.5 -> 0 | AP15: =0/157.5 -> 0 | AQ15: =0/157.5 -> 0 | AR15: =0/157.5 -> 0 | AS15: =0/165 -> 0 | AT15: =0/172.5 -> 0 | AU15: =0/172.5 -> 0 | AV15: =0/172.5 -> 0 | AW15: =0/172.5 -> 0 | AX15: =0/172.5 -> 0 | AY15: =0/172.5 -> 0 | AZ15: =(0)/150 -> 0 | BA15: =(0)/150 -> 0 | BB15: =(0)/150 -> 0 | BC15: =(0)/150 -> 0 | BD15: =(0)/150 -> 0 | BE15: =(0)/150 -> 0 | BF15: =(0)/150 -> 0 | BG15: =0/142.5 -> 0 | BH15: =0/142.5 -> 0 | BI15: =0/142.5 -> 0 | BJ15: =0/142.5 -> 0 | BK15: =0/142.5 -> 0 | BL15: =0/172.5 -> 0 | BM15: =0/172.5 -> 0 | BN15: =0/172.5 -> 0 | BO15: =0/157.5 -> 0 | BP15: =0/157.5 -> 0 | BQ15: =0/157.5 -> 0 | BR15: =0/157.5 -> 0 | BS15: =0/157.5 -> 0 | BT15: =0/172.5 -> 0 | BU15: =0/172.5 -> 0 | BV15: =0/172.5 -> 0 | BW15: =0/157.5 -> 0 | BX15: =0/157.5 -> 0 | BY15: =0/157.5 -> 0 | BZ15: =0/157.5 -> 0 | CA15: =0/157.5 -> 0 | CB15: =0/172.5 -> 0 | CC15: =0/172.5 -> 0 | CD15: =0/172.5 -> 0 | CE15: =0/157.5 -> 0 | CF15: =0/157.5 -> 0 | CG15: =0/157.5 -> 0 | CH15: =0/157.5 -> 0 | CI15: =0/157.5 -> 0 | CJ15: =0/172.5 -> 0 | CK15: =0/172.5 -> 0 | CL15: =0/172.5 -> 0 | CM15: =0/142.5 -> 0 | CN15: =0/142.5 -> 0 | CO15: =0/142.5 -> 0 | CP15: =0/142.5 -> 0 | CQ15: =0/142.5 -> 0 | CR15: =0/172.5 -> 0 | CS15: =0/172.5 -> 0 | CT15: =0/172.5 -> 0
N16: 実績 | O16: =(0+3+1+0.75+1.25)/120 -> 0.05 | P16: =(0)/120 -> 0 | Q16: =(0)/120 -> 0 | R16: =(0)/120 -> 0 | S16: =(0+10+1+3.5)/120 -> 0.12083333 | T16: =(5+6.5+4+2.5)/120 -> 0.15 | U16: =(0)/120 -> 0 | V16: =(0)/142.5 -> 0 | W16: =(0)/142.5 -> 0 | X16: =(0)/142.5 -> 0 | Y16: =(0)/142.5 -> 0 | Z16: =(0)/142.5 -> 0 | AA16: =(0)/142.5 -> 0 | AB16: =0/165 -> 0 | AC16: =0/165 -> 0 | AD16: =0/165 -> 0 | AE16: =0/165 -> 0 | AF16: =0/165 -> 0 | AG16: =0/165 -> 0 | AH16: =(0)/165 -> 0 | AI16: =(0)/165 -> 0 | AJ16: =(0)/165 -> 0 | AK16: =(0)/165 -> 0 | AL16: =(0)/165 -> 0 | AM16: =(0)/165 -> 0 | AN16: =0/157.5 -> 0 | AO16: =0/157.5 -> 0 | AP16: =0/157.5 -> 0 | AQ16: =0/157.5 -> 0 | AR16: =0/157.5 -> 0 | AS16: =0/165 -> 0 | AT16: =0/172.5 -> 0 | AU16: =0/172.5 -> 0 | AV16: =0/172.5 -> 0 | AW16: =0/172.5 -> 0 | AX16: =0/172.5 -> 0 | AY16: =0/172.5 -> 0 | AZ16: =(0)/150 -> 0 | BA16: =(0)/150 -> 0 | BB16: =(0)/150 -> 0 | BC16: =(0)/150 -> 0 | BD16: =(0)/150 -> 0 | BE16: =(0)/150 -> 0 | BF16: =(0)/150 -> 0 | BG16: =0/142.5 -> 0 | BH16: =0/142.5 -> 0 | BI16: =0/142.5 -> 0 | BJ16: =0/142.5 -> 0 | BK16: =0/142.5 -> 0 | BL16: =0/172.5 -> 0 | BM16: =0/172.5 -> 0 | BN16: =0/172.5 -> 0 | BO16: =0/157.5 -> 0 | BP16: =0/157.5 -> 0 | BQ16: =0/157.5 -> 0 | BR16: =0/157.5 -> 0 | BS16: =0/157.5 -> 0 | BT16: =0/172.5 -> 0 | BU16: =0/172.5 -> 0 | BV16: =0/172.5 -> 0 | BW16: =0/157.5 -> 0 | BX16: =0/157.5 -> 0 | BY16: =0/157.5 -> 0 | BZ16: =0/157.5 -> 0 | CA16: =0/157.5 -> 0 | CB16: =0/172.5 -> 0 | CC16: =0/172.5 -> 0 | CD16: =0/172.5 -> 0 | CE16: =0/157.5 -> 0 | CF16: =0/157.5 -> 0 | CG16: =0/157.5 -> 0 | CH16: =0/157.5 -> 0 | CI16: =0/157.5 -> 0 | CJ16: =0/172.5 -> 0 | CK16: =0/172.5 -> 0 | CL16: =0/172.5 -> 0 | CM16: =0/142.5 -> 0 | CN16: =0/142.5 -> 0 | CO16: =0/142.5 -> 0 | CP16: =0/142.5 -> 0 | CQ16: =0/142.5 -> 0 | CR16: =0/172.5 -> 0 | CS16: =0/172.5 -> 0 | CT16: =0/172.5 -> 0
A17: 6 | B17: 完了 | C17: その他 | D17: 永盛 | E17: PR15 | F17: PD00400226 | G17: 【LISA】【フィデア】(1E)(1Y)銀行合併対応 開発フェーズ（LISA） | H17: =SUM(AZ17:BF17) -> 0 | I17: =SUM(AZ18:BF18) -> 0 | N17: 計画 | O17: =(2)/120 -> 0.016666667 | P17: =(0)/120 -> 0 | Q17: =(3)/120 -> 0.025 | R17: =(0)/120 -> 0 | S17: =(0)/120 -> 0 | T17: =(0)/120 -> 0 | U17: =(0)/120 -> 0 | V17: =(3)/142.5 -> 0.021052632 | W17: =(0)/142.5 -> 0 | X17: =(5)/142.5 -> 0.035087719 | Y17: =(0)/142.5 -> 0 | Z17: =(0)/142.5 -> 0 | AA17: =(0)/142.5 -> 0 | AB17: =(5)/165 -> 0.03030303 | AC17: =(0)/165 -> 0 | AD17: =(5)/165 -> 0.03030303 | AE17: =(0)/165 -> 0 | AF17: =(0)/165 -> 0 | AG17: =(0)/165 -> 0 | AH17: =(0)/165 -> 0 | AI17: =(0)/165 -> 0 | AJ17: =(0)/165 -> 0 | AK17: =(0)/165 -> 0 | AL17: =(0)/165 -> 0 | AM17: =(0)/165 -> 0 | AN17: =0/157.5 -> 0 | AO17: =0/157.5 -> 0 | AP17: =0/157.5 -> 0 | AQ17: =0/157.5 -> 0 | AR17: =0/157.5 -> 0 | AS17: =0/165 -> 0 | AT17: =0/172.5 -> 0 | AU17: =0/172.5 -> 0 | AV17: =0/172.5 -> 0 | AW17: =0/172.5 -> 0 | AX17: =0/172.5 -> 0 | AY17: =0/172.5 -> 0 | AZ17: =(0)/150 -> 0 | BA17: =(0)/150 -> 0 | BB17: =(0)/150 -> 0 | BC17: =(0)/150 -> 0 | BD17: =(0)/150 -> 0 | BE17: =(0)/150 -> 0 | BF17: =(0)/150 -> 0 | BG17: =0/142.5 -> 0 | BH17: =0/142.5 -> 0 | BI17: =0/142.5 -> 0 | BJ17: =0/142.5 -> 0 | BK17: =0/142.5 -> 0 | BL17: =0/172.5 -> 0 | BM17: =0/172.5 -> 0 | BN17: =0/172.5 -> 0 | BO17: =0/157.5 -> 0 | BP17: =0/157.5 -> 0 | BQ17: =0/157.5 -> 0 | BR17: =0/157.5 -> 0 | BS17: =0/157.5 -> 0 | BT17: =0/172.5 -> 0 | BU17: =0/172.5 -> 0 | BV17: =0/172.5 -> 0 | BW17: =0/157.5 -> 0 | BX17: =0/157.5 -> 0 | BY17: =0/157.5 -> 0 | BZ17: =0/157.5 -> 0 | CA17: =0/157.5 -> 0 | CB17: =0/172.5 -> 0 | CC17: =0/172.5 -> 0 | CD17: =0/172.5 -> 0 | CE17: =0/157.5 -> 0 | CF17: =0/157.5 -> 0 | CG17: =0/157.5 -> 0 | CH17: =0/157.5 -> 0 | CI17: =0/157.5 -> 0 | CJ17: =0/172.5 -> 0 | CK17: =0/172.5 -> 0 | CL17: =0/172.5 -> 0 | CM17: =0/142.5 -> 0 | CN17: =0/142.5 -> 0 | CO17: =0/142.5 -> 0 | CP17: =0/142.5 -> 0 | CQ17: =0/142.5 -> 0 | CR17: =0/172.5 -> 0 | CS17: =0/172.5 -> 0 | CT17: =0/172.5 -> 0
N18: 実績 | O18: =(0+1)/120 -> 0.0083333333 | P18: =(0)/120 -> 0 | Q18: =(1+1)/120 -> 0.016666667 | R18: =(0)/120 -> 0 | S18: =(0)/120 -> 0 | T18: =(0)/120 -> 0 | U18: =(0)/120 -> 0 | V18: =(1.5)/142.5 -> 0.010526316 | W18: =(0)/142.5 -> 0 | X18: =(3)/142.5 -> 0.021052632 | Y18: =(0)/142.5 -> 0 | Z18: =(0)/142.5 -> 0 | AA18: =(0)/142.5 -> 0 | AB18: =(1)/165 -> 0.0060606061 | AC18: =(0)/165 -> 0 | AD18: =(2+3)/165 -> 0.03030303 | AE18: =(0)/165 -> 0 | AF18: =(0)/165 -> 0 | AG18: =(0)/165 -> 0 | AH18: =(0)/165 -> 0 | AI18: =(0)/165 -> 0 | AJ18: =(0)/165 -> 0 | AK18: =(0)/165 -> 0 | AL18: =(0)/165 -> 0 | AM18: =(0)/165 -> 0 | AN18: =0/157.5 -> 0 | AO18: =0/157.5 -> 0 | AP18: =0/157.5 -> 0 | AQ18: =0/157.5 -> 0 | AR18: =0/157.5 -> 0 | AS18: =0/165 -> 0 | AT18: =0/172.5 -> 0 | AU18: =0/172.5 -> 0 | AV18: =0/172.5 -> 0 | AW18: =0/172.5 -> 0 | AX18: =0/172.5 -> 0 | AY18: =0/172.5 -> 0 | AZ18: =(0)/150 -> 0 | BA18: =(0)/150 -> 0 | BB18: =(0)/150 -> 0 | BC18: =(0)/150 -> 0 | BD18: =(0)/150 -> 0 | BE18: =(0)/150 -> 0 | BF18: =(0)/150 -> 0 | BG18: =0/142.5 -> 0 | BH18: =0/142.5 -> 0 | BI18: =0/142.5 -> 0 | BJ18: =0/142.5 -> 0 | BK18: =0/142.5 -> 0 | BL18: =0/172.5 -> 0 | BM18: =0/172.5 -> 0 | BN18: =0/172.5 -> 0 | BO18: =0/157.5 -> 0 | BP18: =0/157.5 -> 0 | BQ18: =0/157.5 -> 0 | BR18: =0/157.5 -> 0 | BS18: =0/157.5 -> 0 | BT18: =0/172.5 -> 0 | BU18: =0/172.5 -> 0 | BV18: =0/172.5 -> 0 | BW18: =0/157.5 -> 0 | BX18: =0/157.5 -> 0 | BY18: =0/157.5 -> 0 | BZ18: =0/157.5 -> 0 | CA18: =0/157.5 -> 0 | CB18: =0/172.5 -> 0 | CC18: =0/172.5 -> 0 | CD18: =0/172.5 -> 0 | CE18: =0/157.5 -> 0 | CF18: =0/157.5 -> 0 | CG18: =0/157.5 -> 0 | CH18: =0/157.5 -> 0 | CI18: =0/157.5 -> 0 | CJ18: =0/172.5 -> 0 | CK18: =0/172.5 -> 0 | CL18: =0/172.5 -> 0 | CM18: =0/142.5 -> 0 | CN18: =0/142.5 -> 0 | CO18: =0/142.5 -> 0 | CP18: =0/142.5 -> 0 | CQ18: =0/142.5 -> 0 | CR18: =0/172.5 -> 0 | CS18: =0/172.5 -> 0 | CT18: =0/172.5 -> 0
A19: 7 | B19: 完了 | C19: 定型 | D19: 山田 | E19: F202 | F19: PB00202062 | G19: 【定型】投資家画面の文言変更 | H19: =SUM(AZ19:BF19) -> 0 | I19: =SUM(AZ20:BF20) -> 0 | N19: 計画 | O19: =(12)/120 -> 0.1 | P19: =(0)/120 -> 0 | Q19: =(0)/120 -> 0 | R19: =(25)/120 -> 0.20833333 | S19: =(0)/120 -> 0 | T19: =(0)/120 -> 0 | U19: =(15)/120 -> 0.125 | V19: =(0)/142.5 -> 0 | W19: =(0)/142.5 -> 0 | X19: =(0)/142.5 -> 0 | Y19: =(0)/142.5 -> 0 | Z19: =(0)/142.5 -> 0 | AA19: =(0)/142.5 -> 0 | AB19: =0/165 -> 0 | AC19: =0/165 -> 0 | AD19: =0/165 -> 0 | AE19: =0/165 -> 0 | AF19: =0/165 -> 0 | AG19: =0/165 -> 0 | AH19: =(0)/165 -> 0 | AI19: =(0)/165 -> 0 | AJ19: =(0)/165 -> 0 | AK19: =(0)/165 -> 0 | AL19: =(0)/165 -> 0 | AM19: =(0)/165 -> 0 | AN19: =0/157.5 -> 0 | AO19: =0/157.5 -> 0 | AP19: =0/157.5 -> 0 | AQ19: =0/157.5 -> 0 | AR19: =0/157.5 -> 0 | AS19: =0/165 -> 0 | AT19: =0/172.5 -> 0 | AU19: =0/172.5 -> 0 | AV19: =0/172.5 -> 0 | AW19: =0/172.5 -> 0 | AX19: =0/172.5 -> 0 | AY19: =0/172.5 -> 0 | AZ19: =(0)/150 -> 0 | BA19: =(0)/150 -> 0 | BB19: =(0)/150 -> 0 | BC19: =(0)/150 -> 0 | BD19: =(0)/150 -> 0 | BE19: =(0)/150 -> 0 | BF19: =(0)/150 -> 0 | BG19: =0/142.5 -> 0 | BH19: =0/142.5 -> 0 | BI19: =0/142.5 -> 0 | BJ19: =0/142.5 -> 0 | BK19: =0/142.5 -> 0 | BL19: =0/172.5 -> 0 | BM19: =0/172.5 -> 0 | BN19: =0/172.5 -> 0 | BO19: =0/157.5 -> 0 | BP19: =0/157.5 -> 0 | BQ19: =0/157.5 -> 0 | BR19: =0/157.5 -> 0 | BS19: =0/157.5 -> 0 | BT19: =0/172.5 -> 0 | BU19: =0/172.5 -> 0 | BV19: =0/172.5 -> 0 | BW19: =0/157.5 -> 0 | BX19: =0/157.5 -> 0 | BY19: =0/157.5 -> 0 | BZ19: =0/157.5 -> 0 | CA19: =0/157.5 -> 0 | CB19: =0/172.5 -> 0 | CC19: =0/172.5 -> 0 | CD19: =0/172.5 -> 0 | CE19: =0/157.5 -> 0 | CF19: =0/157.5 -> 0 | CG19: =0/157.5 -> 0 | CH19: =0/157.5 -> 0 | CI19: =0/157.5 -> 0 | CJ19: =0/172.5 -> 0 | CK19: =0/172.5 -> 0 | CL19: =0/172.5 -> 0 | CM19: =0/142.5 -> 0 | CN19: =0/142.5 -> 0 | CO19: =0/142.5 -> 0 | CP19: =0/142.5 -> 0 | CQ19: =0/142.5 -> 0 | CR19: =0/172.5 -> 0 | CS19: =0/172.5 -> 0 | CT19: =0/172.5 -> 0
N20: 実績 | O20: =(1+4.75+0.5)/120 -> 0.052083333 | P20: =(0)/120 -> 0 | Q20: =(0)/120 -> 0 | R20: =(3.5+16+6+2.5)/120 -> 0.23333333 | S20: =(0)/120 -> 0 | T20: =(0)/120 -> 0 | U20: =(3.5+9+2)/120 -> 0.12083333 | V20: =(0)/142.5 -> 0 | W20: =(0)/142.5 -> 0 | X20: =(0)/142.5 -> 0 | Y20: =(0)/142.5 -> 0 | Z20: =(0)/142.5 -> 0 | AA20: =(0)/142.5 -> 0 | AB20: =0/165 -> 0 | AC20: =0/165 -> 0 | AD20: =0/165 -> 0 | AE20: =0/165 -> 0 | AF20: =0/165 -> 0 | AG20: =0/165 -> 0 | AH20: =(0)/165 -> 0 | AI20: =(0)/165 -> 0 | AJ20: =(0)/165 -> 0 | AK20: =(0)/165 -> 0 | AL20: =(0)/165 -> 0 | AM20: =(0)/165 -> 0 | AN20: =0/157.5 -> 0 | AO20: =0/157.5 -> 0 | AP20: =0/157.5 -> 0 | AQ20: =0/157.5 -> 0 | AR20: =0/157.5 -> 0 | AS20: =0/165 -> 0 | AT20: =0/172.5 -> 0 | AU20: =0/172.5 -> 0 | AV20: =0/172.5 -> 0 | AW20: =0/172.5 -> 0 | AX20: =0/172.5 -> 0 | AY20: =0/172.5 -> 0 | AZ20: =(0)/150 -> 0 | BA20: =(0)/150 -> 0 | BB20: =(0)/150 -> 0 | BC20: =(0)/150 -> 0 | BD20: =(0)/150 -> 0 | BE20: =(0)/150 -> 0 | BF20: =(0)/150 -> 0 | BG20: =0/142.5 -> 0 | BH20: =0/142.5 -> 0 | BI20: =0/142.5 -> 0 | BJ20: =0/142.5 -> 0 | BK20: =0/142.5 -> 0 | BL20: =0/172.5 -> 0 | BM20: =0/172.5 -> 0 | BN20: =0/172.5 -> 0 | BO20: =0/157.5 -> 0 | BP20: =0/157.5 -> 0 | BQ20: =0/157.5 -> 0 | BR20: =0/157.5 -> 0 | BS20: =0/157.5 -> 0 | BT20: =0/172.5 -> 0 | BU20: =0/172.5 -> 0 | BV20: =0/172.5 -> 0 | BW20: =0/157.5 -> 0 | BX20: =0/157.5 -> 0 | BY20: =0/157.5 -> 0 | BZ20: =0/157.5 -> 0 | CA20: =0/157.5 -> 0 | CB20: =0/172.5 -> 0 | CC20: =0/172.5 -> 0 | CD20: =0/172.5 -> 0 | CE20: =0/157.5 -> 0 | CF20: =0/157.5 -> 0 | CG20: =0/157.5 -> 0 | CH20: =0/157.5 -> 0 | CI20: =0/157.5 -> 0 | CJ20: =0/172.5 -> 0 | CK20: =0/172.5 -> 0 | CL20: =0/172.5 -> 0 | CM20: =0/142.5 -> 0 | CN20: =0/142.5 -> 0 | CO20: =0/142.5 -> 0 | CP20: =0/142.5 -> 0 | CQ20: =0/142.5 -> 0 | CR20: =0/172.5 -> 0 | CS20: =0/172.5 -> 0 | CT20: =0/172.5 -> 0
A21: 8 | B21: 完了 | C21: 定型 | D21: 山田 | E21: F203 | F21: PB00202085 | G21: 【定型】株式委託手数料プランの名前変更 | H21: =SUM(AZ21:BF21) -> 0 | I21: =SUM(AZ22:BF22) -> 0 | N21: 計画 | O21: =(5)/120 -> 0.041666667 | P21: =(0)/120 -> 0 | Q21: =(0)/120 -> 0 | R21: =(0)/120 -> 0 | S21: =(0)/120 -> 0 | T21: =(30)/120 -> 0.25 | U21: =(0)/120 -> 0 | V21: =(0)/142.5 -> 0 | W21: =(0)/142.5 -> 0 | X21: =(0)/142.5 -> 0 | Y21: =(0)/142.5 -> 0 | Z21: =(0)/142.5 -> 0 | AA21: =(0)/142.5 -> 0 | AB21: =0/165 -> 0 | AC21: =0/165 -> 0 | AD21: =0/165 -> 0 | AE21: =0/165 -> 0 | AF21: =0/165 -> 0 | AG21: =0/165 -> 0 | AH21: =(0)/165 -> 0 | AI21: =(0)/165 -> 0 | AJ21: =(0)/165 -> 0 | AK21: =(0)/165 -> 0 | AL21: =(0)/165 -> 0 | AM21: =(0)/165 -> 0 | AN21: =0/157.5 -> 0 | AO21: =0/157.5 -> 0 | AP21: =0/157.5 -> 0 | AQ21: =0/157.5 -> 0 | AR21: =0/157.5 -> 0 | AS21: =0/165 -> 0 | AT21: =0/172.5 -> 0 | AU21: =0/172.5 -> 0 | AV21: =0/172.5 -> 0 | AW21: =0/172.5 -> 0 | AX21: =0/172.5 -> 0 | AY21: =0/172.5 -> 0 | AZ21: =(0)/150 -> 0 | BA21: =(0)/150 -> 0 | BB21: =(0)/150 -> 0 | BC21: =(0)/150 -> 0 | BD21: =(0)/150 -> 0 | BE21: =(0)/150 -> 0 | BF21: =(0)/150 -> 0 | BG21: =0/142.5 -> 0 | BH21: =0/142.5 -> 0 | BI21: =0/142.5 -> 0 | BJ21: =0/142.5 -> 0 | BK21: =0/142.5 -> 0 | BL21: =0/172.5 -> 0 | BM21: =0/172.5 -> 0 | BN21: =0/172.5 -> 0 | BO21: =0/157.5 -> 0 | BP21: =0/157.5 -> 0 | BQ21: =0/157.5 -> 0 | BR21: =0/157.5 -> 0 | BS21: =0/157.5 -> 0 | BT21: =0/172.5 -> 0 | BU21: =0/172.5 -> 0 | BV21: =0/172.5 -> 0 | BW21: =0/157.5 -> 0 | BX21: =0/157.5 -> 0 | BY21: =0/157.5 -> 0 | BZ21: =0/157.5 -> 0 | CA21: =0/157.5 -> 0 | CB21: =0/172.5 -> 0 | CC21: =0/172.5 -> 0 | CD21: =0/172.5 -> 0 | CE21: =0/157.5 -> 0 | CF21: =0/157.5 -> 0 | CG21: =0/157.5 -> 0 | CH21: =0/157.5 -> 0 | CI21: =0/157.5 -> 0 | CJ21: =0/172.5 -> 0 | CK21: =0/172.5 -> 0 | CL21: =0/172.5 -> 0 | CM21: =0/142.5 -> 0 | CN21: =0/142.5 -> 0 | CO21: =0/142.5 -> 0 | CP21: =0/142.5 -> 0 | CQ21: =0/142.5 -> 0 | CR21: =0/172.5 -> 0 | CS21: =0/172.5 -> 0 | CT21: =0/172.5 -> 0
N22: 実績 | O22: =(1.5+3.75+1+0.75)/120 -> 0.058333333 | P22: =(0)/120 -> 0 | Q22: =(0)/120 -> 0 | R22: =(0)/120 -> 0 | S22: =(0+1)/120 -> 0.0083333333 | T22: =(0+13.5+6+2.5)/120 -> 0.18333333 | U22: =(0)/120 -> 0 | V22: =(0)/142.5 -> 0 | W22: =(0)/142.5 -> 0 | X22: =(0)/142.5 -> 0 | Y22: =(0)/142.5 -> 0 | Z22: =(0)/142.5 -> 0 | AA22: =(0)/142.5 -> 0 | AB22: =0/165 -> 0 | AC22: =0/165 -> 0 | AD22: =0/165 -> 0 | AE22: =0/165 -> 0 | AF22: =0/165 -> 0 | AG22: =0/165 -> 0 | AH22: =(0)/165 -> 0 | AI22: =(0)/165 -> 0 | AJ22: =(0)/165 -> 0 | AK22: =(0)/165 -> 0 | AL22: =(0)/165 -> 0 | AM22: =(0)/165 -> 0 | AN22: =0/157.5 -> 0 | AO22: =0/157.5 -> 0 | AP22: =0/157.5 -> 0 | AQ22: =0/157.5 -> 0 | AR22: =0/157.5 -> 0 | AS22: =0/165 -> 0 | AT22: =0/172.5 -> 0 | AU22: =0/172.5 -> 0 | AV22: =0/172.5 -> 0 | AW22: =0/172.5 -> 0 | AX22: =0/172.5 -> 0 | AY22: =0/172.5 -> 0 | AZ22: =(0)/150 -> 0 | BA22: =(0)/150 -> 0 | BB22: =(0)/150 -> 0 | BC22: =(0)/150 -> 0 | BD22: =(0)/150 -> 0 | BE22: =(0)/150 -> 0 | BF22: =(0)/150 -> 0 | BG22: =0/142.5 -> 0 | BH22: =0/142.5 -> 0 | BI22: =0/142.5 -> 0 | BJ22: =0/142.5 -> 0 | BK22: =0/142.5 -> 0 | BL22: =0/172.5 -> 0 | BM22: =0/172.5 -> 0 | BN22: =0/172.5 -> 0 | BO22: =0/157.5 -> 0 | BP22: =0/157.5 -> 0 | BQ22: =0/157.5 -> 0 | BR22: =0/157.5 -> 0 | BS22: =0/157.5 -> 0 | BT22: =0/172.5 -> 0 | BU22: =0/172.5 -> 0 | BV22: =0/172.5 -> 0 | BW22: =0/157.5 -> 0 | BX22: =0/157.5 -> 0 | BY22: =0/157.5 -> 0 | BZ22: =0/157.5 -> 0 | CA22: =0/157.5 -> 0 | CB22: =0/172.5 -> 0 | CC22: =0/172.5 -> 0 | CD22: =0/172.5 -> 0 | CE22: =0/157.5 -> 0 | CF22: =0/157.5 -> 0 | CG22: =0/157.5 -> 0 | CH22: =0/157.5 -> 0 | CI22: =0/157.5 -> 0 | CJ22: =0/172.5 -> 0 | CK22: =0/172.5 -> 0 | CL22: =0/172.5 -> 0 | CM22: =0/142.5 -> 0 | CN22: =0/142.5 -> 0 | CO22: =0/142.5 -> 0 | CP22: =0/142.5 -> 0 | CQ22: =0/142.5 -> 0 | CR22: =0/172.5 -> 0 | CS22: =0/172.5 -> 0 | CT22: =0/172.5 -> 0
A23: 9 | B23: 完了 | C23: 定型 | D23: 山田 | E23: F204 | G23: 【定型】クイック入金ページの注意文言修正依頼 | H23: =SUM(AZ23:BF23) -> 0 | I23: =SUM(AZ24:BF24) -> 0 | N23: 計画 | O23: =(5)/120 -> 0.041666667 | P23: =(0)/120 -> 0 | Q23: =(6.5)/120 -> 0.054166667 | R23: =(0)/120 -> 0 | S23: =(11.5)/120 -> 0.095833333 | T23: =(0)/120 -> 0 | U23: =(2)/120 -> 0.016666667 | V23: =(0)/142.5 -> 0 | W23: =(0)/142.5 -> 0 | X23: =(0)/142.5 -> 0 | Y23: =(0)/142.5 -> 0 | Z23: =(0)/142.5 -> 0 | AA23: =(0)/142.5 -> 0 | AB23: =0/165 -> 0 | AC23: =0/165 -> 0 | AD23: =0/165 -> 0 | AE23: =0/165 -> 0 | AF23: =0/165 -> 0 | AG23: =0/165 -> 0 | AH23: =(0)/165 -> 0 | AI23: =(0)/165 -> 0 | AJ23: =(0)/165 -> 0 | AK23: =(0)/165 -> 0 | AL23: =(0)/165 -> 0 | AM23: =(0)/165 -> 0 | AN23: =0/157.5 -> 0 | AO23: =0/157.5 -> 0 | AP23: =0/157.5 -> 0 | AQ23: =0/157.5 -> 0 | AR23: =0/157.5 -> 0 | AS23: =0/165 -> 0 | AT23: =0/172.5 -> 0 | AU23: =0/172.5 -> 0 | AV23: =0/172.5 -> 0 | AW23: =0/172.5 -> 0 | AX23: =0/172.5 -> 0 | AY23: =0/172.5 -> 0 | AZ23: =(0)/150 -> 0 | BA23: =(0)/150 -> 0 | BB23: =(0)/150 -> 0 | BC23: =(0)/150 -> 0 | BD23: =(0)/150 -> 0 | BE23: =(0)/150 -> 0 | BF23: =(0)/150 -> 0 | BG23: =0/142.5 -> 0 | BH23: =0/142.5 -> 0 | BI23: =0/142.5 -> 0 | BJ23: =0/142.5 -> 0 | BK23: =0/142.5 -> 0 | BL23: =0/172.5 -> 0 | BM23: =0/172.5 -> 0 | BN23: =0/172.5 -> 0 | BO23: =0/157.5 -> 0 | BP23: =0/157.5 -> 0 | BQ23: =0/157.5 -> 0 | BR23: =0/157.5 -> 0 | BS23: =0/157.5 -> 0 | BT23: =0/172.5 -> 0 | BU23: =0/172.5 -> 0 | BV23: =0/172.5 -> 0 | BW23: =0/157.5 -> 0 | BX23: =0/157.5 -> 0 | BY23: =0/157.5 -> 0 | BZ23: =0/157.5 -> 0 | CA23: =0/157.5 -> 0 | CB23: =0/172.5 -> 0 | CC23: =0/172.5 -> 0 | CD23: =0/172.5 -> 0 | CE23: =0/157.5 -> 0 | CF23: =0/157.5 -> 0 | CG23: =0/157.5 -> 0 | CH23: =0/157.5 -> 0 | CI23: =0/157.5 -> 0 | CJ23: =0/172.5 -> 0 | CK23: =0/172.5 -> 0 | CL23: =0/172.5 -> 0 | CM23: =0/142.5 -> 0 | CN23: =0/142.5 -> 0 | CO23: =0/142.5 -> 0 | CP23: =0/142.5 -> 0 | CQ23: =0/142.5 -> 0 | CR23: =0/172.5 -> 0 | CS23: =0/172.5 -> 0 | CT23: =0/172.5 -> 0
